Workbook

Sheet PETUNJUK
A1: TEMU KOPI / PANDUAN OPERASIONAL
A3: MULAI DI SINI | B3: Data dengan ID berawalan CONTOH- adalah simulasi. Hapus/ganti sebelum transaksi nyata. Semua angka contoh bukan harga resmi.
A4: URUTAN SETUP | B4: Isi MASTER MENU dan MASTER BAHAN → RESEP DAN HPP → cek kelengkapan → isi stok awal → mulai transaksi.
A5: URUTAN HARIAN | B5: Catat STOK MASUK; PERGERAKAN STOK; TRANSAKSI PENJUALAN dan DETAIL TRANSAKSI; refund berhasil; PENGELUARAN; tutup SHIFT KASIR; tinjau laporan.
A6: KUNING MUDA | B6: Kolom input pengguna. Kode/nomor transaksi harus unik. Tanggal dan jam dicatat dalam WIB.
A7: HIJAU MUDA | B7: Kolom rumus otomatis. Jangan ketik di atas rumus. Saat impor Google Sheets, periksa kembali validasi dan tabel.
A8: STATUS MERAH | B8: Perlu tindakan: Habis, Menipis, HPP belum lengkap, atau selisih kas Kurang. Teks status tetap dapat dibaca tanpa warna.
A9: MASTER MENU | B9: Isi ID, nama, kategori, jenis, varian, harga jual, status, tiket dapur, catatan, tanggal. Harga contoh hanya simulasi.
A10: MASTER BAHAN | B10: Isi stok awal/minimum, harga beli total untuk jumlah pembelian dalam satuan dasar (gram/ml/pcs); biaya per satuan dihitung.
A11: RESEP DAN HPP | B11: Isi ID menu, ID bahan dan jumlah per porsi. Satu baris untuk satu bahan. Biaya, total HPP, laba, margin, status otomatis.
A12: STOK MASUK / PERGERAKAN | B12: Isi pembelian dan pemakaian/waste/penyesuaian/retur. Penyesuaian bertanda + atau −; retur ke supplier bertanda positif dan mengurangi stok.
A13: RINGKASAN STOK | B13: Stok awal + masuk − pemakaian − waste + penyesuaian − retur. Nilai persediaan hanya estimasi biaya terkini.
A14: TRANSAKSI / DETAIL | B14: Isi satu pesanan per baris header, satu item per baris detail. Alokasikan diskon/refund ke item hingga jumlahnya sama dengan header.
... A35: CHECKLIST HARIAN | B35: Gunakan satu ID per tanggal dan shift; satu baris mewakili satu item pemeriksaan.

Sheet MASTER MENU
A1: MASTER MENU
A2: Isi sel kuning. Semua entri awal CONTOH.
A3: ISI MANUAL | B3: HASIL OTOMATIS | C3: ID CONTOH- = simulasi
A4: ID menu | B4: Nama menu | C4: Kategori | D4: Jenis | E4: Varian | F4: Harga jual | G4: Status | H4: Dikirim ke dapur | I4: Catatan | J4: Tanggal diperbarui
A5: CONTOH-M01 | B5: Kopi Susu Gula Aren | C5: Kopi | D5: Minuman | E5: Reguler | F5: 28000 | G5: Aktif | H5: Ya | I5: CONTOH - ganti sesuai menu final | J5: 46325
A6: CONTOH-M02 | B6: Americano | C6: Kopi | D6: Minuman | E6: Ice | F6: 25000 | G6: Aktif | H6: Ya | I6: CONTOH - ganti sesuai menu final | J6: 46325
A7: CONTOH-M03 | B7: Latte | C7: Kopi | D7: Minuman | E7: Hot | F7: 32000 | G7: Aktif | H7: Ya | I7: CONTOH - ganti sesuai menu final | J7: 46325
A8: CONTOH-M04 | B8: Matcha Latte | C8: Non-kopi | D8: Minuman | E8: Ice | F8: 33000 | G8: Aktif | H8: Ya | I8: CONTOH - ganti sesuai menu final | J8: 46325
A9: CONTOH-M05 | B9: Teh Lemon | C9: Teh | D9: Minuman | E9: Ice | F9: 22000 | G9: Aktif | H9: Ya | I9: CONTOH - ganti sesuai menu final | J9: 46325
A10: CONTOH-M06 | B10: Croissant Butter | C10: Pastry | D10: Makanan | E10: Reguler | F10: 27000 | G10: Aktif | H10: Ya | I10: CONTOH - ganti sesuai menu final | J10: 46325
A11: CONTOH-M07 | B11: Nasi Goreng | C11: Makanan berat | D11: Makanan | E11: Reguler | F11: 42000 | G11: Aktif | H11: Ya | I11: CONTOH - ganti sesuai menu final | J11: 46325
A12: CONTOH-M08 | B12: Kentang Goreng | C12: Camilan | D12: Makanan | E12: Reguler | F12: 26000 | G12: Aktif | H12: Ya | I12: CONTOH - ganti sesuai menu final | J12: 46325
A13: CONTOH-M09 | B13: Espresso | C13: Kopi | D13: Minuman | E13: Single | F13: 20000 | G13: Aktif | H13: Ya | I13: CONTOH - ganti sesuai menu final | J13: 46325
A14: CONTOH-M10 | B14: Roti Bakar | C14: Camilan | D14: Makanan | E14: Reguler | F14: 24000 | G14: Aktif | H14: Ya | I14: CONTOH - ganti sesuai menu final | J14: 46325

Sheet MASTER BAHAN
A1: MASTER BAHAN
A2: Harga beli = total tagihan untuk jumlah pembelian dalam satuan dasar; bukan harga per kemasan.
A3: ISI MANUAL | B3: HASIL OTOMATIS | C3: ID CONTOH- = simulasi
A4: ID bahan | B4: Nama bahan | C4: Kategori bahan | D4: Satuan dasar | E4: Stok awal | F4: Stok minimum | G4: Harga beli | H4: Jumlah pembelian | I4: Biaya per satuan dasar | J4: Supplier | K4: Status stok | L4: Tanggal diperbarui
A5: CONTOH-B01 | B5: Biji kopi | C5: Kopi | D5: gram | E5: 3000 | F5: 500 | G5: 150000 | H5: 1000 | I5: =IF(A5="","",IF(OR(NOT(ISNUMBER(G5)),NOT(ISNUMBER(H5)),H5<=0),"BELUM LENGKAP",ROUND(G5/H5,4))) -> 150 | J5: Supplier CONTOH | K5: =IF(A5="","",IF(COUNTIFS('RINGKASAN STOK'!$A$5:$A$504,A5)=0,"BELUM LENGKAP",INDEX('RINGKASAN STOK'!$J$5:$J$504,MATCH(A5,'RINGKASAN STOK'!$A$5:$A$504,0)))) -> Aman | L5: 46325
A6: CONTOH-B02 | B6: Susu UHT | C6: Susu | D6: ml | E6: 8000 | F6: 2000 | G6: 24000 | H6: 1000 | I6: =IF(A6="","",IF(OR(NOT(ISNUMBER(G6)),NOT(ISNUMBER(H6)),H6<=0),"BELUM LENGKAP",ROUND(G6/H6,4))) -> 24 | J6: Supplier CONTOH | K6: =IF(A6="","",IF(COUNTIFS('RINGKASAN STOK'!$A$5:$A$504,A6)=0,"BELUM LENGKAP",INDEX('RINGKASAN STOK'!$J$5:$J$504,MATCH(A6,'RINGKASAN STOK'!$A$5:$A$504,0)))) -> Aman | L6: 46325
A7: CONTOH-B03 | B7: Gula aren | C7: Pemanis | D7: ml | E7: 2000 | F7: 500 | G7: 40000 | H7: 1000 | I7: =IF(A7="","",IF(OR(NOT(ISNUMBER(G7)),NOT(ISNUMBER(H7)),H7<=0),"BELUM LENGKAP",ROUND(G7/H7,4))) -> 40 | J7: Supplier CONTOH | K7: =IF(A7="","",IF(COUNTIFS('RINGKASAN STOK'!$A$5:$A$504,A7)=0,"BELUM LENGKAP",INDEX('RINGKASAN STOK'!$J$5:$J$504,MATCH(A7,'RINGKASAN STOK'!$A$5:$A$504,0)))) -> Aman | L7: 46325
A8: CONTOH-B04 | B8: Air mineral | C8: Lainnya | D8: ml | E8: 20000 | F8: 3000 | G8: 8000 | H8: 10000 | I8: =IF(A8="","",IF(OR(NOT(ISNUMBER(G8)),NOT(ISNUMBER(H8)),H8<=0),"BELUM LENGKAP",ROUND(G8/H8,4))) -> 0.8 | J8: Supplier CONTOH | K8: =IF(A8="","",IF(COUNTIFS('RINGKASAN STOK'!$A$5:$A$504,A8)=0,"BELUM LENGKAP",INDEX('RINGKASAN STOK'!$J$5:$J$504,MATCH(A8,'RINGKASAN STOK'!$A$5:$A$504,0)))) -> Aman | L8: 46325
A9: CONTOH-B05 | B9: Bubuk matcha | C9: Bubuk | D9: gram | E9: 500 | F9: 100 | G9: 220000 | H9: 1000 | I9: =IF(A9="","",IF(OR(NOT(ISNUMBER(G9)),NOT(ISNUMBER(H9)),H9<=0),"BELUM LENGKAP",ROUND(G9/H9,4))) -> 220 | J9: Supplier CONTOH | K9: =IF(A9="","",IF(COUNTIFS('RINGKASAN STOK'!$A$5:$A$504,A9)=0,"BELUM LENGKAP",INDEX('RINGKASAN STOK'!$J$5:$J$504,MATCH(A9,'RINGKASAN STOK'!$A$5:$A$504,0)))) -> Aman | L9: 46325
A10: CONTOH-B06 | B10: Teh celup | C10: Teh | D10: pcs | E10: 120 | F10: 20 | G10: 40000 | H10: 100 | I10: =IF(A10="","",IF(OR(NOT(ISNUMBER(G10)),NOT(ISNUMBER(H10)),H10<=0),"BELUM LENGKAP",ROUND(G10/H10,4))) -> 400 | J10: Supplier CONTOH | K10: =IF(A10="","",IF(COUNTIFS('RINGKASAN STOK'!$A$5:$A$504,A10)=0,"BELUM LENGKAP",INDEX('RINGKASAN STOK'!$J$5:$J$504,MATCH(A10,'RINGKASAN STOK'!$A$5:$A$504,0)))) -> Aman | L10: 46325
A11: CONTOH-B07 | B11: Lemon | C11: Buah | D11: gram | E11: 1500 | F11: 200 | G11: 30000 | H11: 1000 | I11: =IF(A11="","",IF(OR(NOT(ISNUMBER(G11)),NOT(ISNUMBER(H11)),H11<=0),"BELUM LENGKAP",ROUND(G11/H11,4))) -> 30 | J11: Supplier CONTOH | K11: =IF(A11="","",IF(COUNTIFS('RINGKASAN STOK'!$A$5:$A$504,A11)=0,"BELUM LENGKAP",INDEX('RINGKASAN STOK'!$J$5:$J$504,MATCH(A11,'RINGKASAN STOK'!$A$5:$A$504,0)))) -> Aman | L11: 46325
A12: CONTOH-B08 | B12: Croissant beku | C12: Pastry | D12: pcs | E12: 30 | F12: 8 | G12: 150000 | H12: 20 | I12: =IF(A12="","",IF(OR(NOT(ISNUMBER(G12)),NOT(ISNUMBER(H12)),H12<=0),"BELUM LENGKAP",ROUND(G12/H12,4))) -> 7500 | J12: Supplier CONTOH | K12: =IF(A12="","",IF(COUNTIFS('RINGKASAN STOK'!$A$5:$A$504,A12)=0,"BELUM LENGKAP",INDEX('RINGKASAN STOK'!$J$5:$J$504,MATCH(A12,'RINGKASAN STOK'!$A$5:$A$504,0)))) -> Aman | L12: 46325
A13: CONTOH-B09 | B13: Beras | C13: Bahan dapur | D13: gram | E13: 5000 | F13: 1000 | G13: 17000 | H13: 1000 | I13: =IF(A13="","",IF(OR(NOT(ISNUMBER(G13)),NOT(ISNUMBER(H13)),H13<=0),"BELUM LENGKAP",ROUND(G13/H13,4))) -> 17 | J13: Supplier CONTOH | K13: =IF(A13="","",IF(COUNTIFS('RINGKASAN STOK'!$A$5:$A$504,A13)=0,"BELUM LENGKAP",INDEX('RINGKASAN STOK'!$J$5:$J$504,MATCH(A13,'RINGKASAN STOK'!$A$5:$A$504,0)))) -> Aman | L13: 46325
A14: CONTOH-B10 | B14: Telur | C14: Bahan dapur | D14: pcs | E14: 80 | F14: 15 | G14: 30000 | H14: 30 | I14: =IF(A14="","",IF(OR(NOT(ISNUMBER(G14)),NOT(ISNUMBER(H14)),H14<=0),"BELUM LENGKAP",ROUND(G14/H14,4))) -> 1000 | J14: Supplier CONTOH | K14: =IF(A14="","",IF(COUNTIFS('RINGKASAN STOK'!$A$5:$A$504,A14)=0,"BELUM LENGKAP",INDEX('RINGKASAN STOK'!$J$5:$J$504,MATCH(A14,'RINGKASAN STOK'!$A$5:$A$504,0)))) -> Aman | L14: 46325
A15: CONTOH-B11 | B15: Kentang beku | C15: Bahan dapur | D15: gram | E15: 3000 | F15: 500 | G15: 50000 | H15: 1000 | I15: =IF(A15="","",IF(OR(NOT(ISNUMBER(G15)),NOT(ISNUMBER(H15)),H15<=0),"BELUM LENGKAP",ROUND(G15/H15,4))) -> 50 | J15: Supplier CONTOH | K15: =IF(A15="","",IF(COUNTIFS('RINGKASAN STOK'!$A$5:$A$504,A15)=0,"BELUM LENGKAP",INDEX('RINGKASAN STOK'!$J$5:$J$504,MATCH(A15,'RINGKASAN STOK'!$A$5:$A$504,0)))) -> Aman | L15: 46325
A16: CONTOH-B12 | B16: Roti | C16: Bahan dapur | D16: pcs | E16: 35 | F16: 10 | G16: 50000 | H16: 20 | I16: =IF(A16="","",IF(OR(NOT(ISNUMBER(G16)),NOT(ISNUMBER(H16)),H16<=0),"BELUM LENGKAP",ROUND(G16/H16,4))) -> 2500 | J16: Supplier CONTOH | K16: =IF(A16="","",IF(COUNTIFS('RINGKASAN STOK'!$A$5:$A$504,A16)=0,"BELUM LENGKAP",INDEX('RINGKASAN STOK'!$J$5:$J$504,MATCH(A16,'RINGKASAN STOK'!$A$5:$A$504,0)))) -> Aman | L16: 46325
I17: =IF(A17="","",IF(OR(NOT(ISNUMBER(G17)),NOT(ISNUMBER(H17)),H17<=0),"BELUM LENGKAP",ROUND(G17/H17,4))) | K17: =IF(A17="","",IF(COUNTIFS('RINGKASAN STOK'!$A$5:$A$504,A17)=0,"BELUM LENGKAP",INDEX('RINGKASAN STOK'!$J$5:$J$504,MATCH(A17,'RINGKASAN STOK'!$A$5:$A$504,0))))
I18: =IF(A18="","",IF(OR(NOT(ISNUMBER(G18)),NOT(ISNUMBER(H18)),H18<=0),"BELUM LENGKAP",ROUND(G18/H18,4))) | K18: =IF(A18="","",IF(COUNTIFS('RINGKASAN STOK'!$A$5:$A$504,A18)=0,"BELUM LENGKAP",INDEX('RINGKASAN STOK'!$J$5:$J$504,MATCH(A18,'RINGKASAN STOK'!$A$5:$A$504,0))))
I19: =IF(A19="","",IF(OR(NOT(ISNUMBER(G19)),NOT(ISNUMBER(H19)),H19<=0),"BELUM LENGKAP",ROUND(G19/H19,4))) | K19: =IF(A19="","",IF(COUNTIFS('RINGKASAN STOK'!$A$5:$A$504,A19)=0,"BELUM LENGKAP",INDEX('RINGKASAN STOK'!$J$5:$J$504,MATCH(A19,'RINGKASAN STOK'!$A$5:$A$504,0))))
I20: =IF(A20="","",IF(OR(NOT(ISNUMBER(G20)),NOT(ISNUMBER(H20)),H20<=0),"BELUM LENGKAP",ROUND(G20/H20,4))) | K20: =IF(A20="","",IF(COUNTIFS('RINGKASAN STOK'!$A$5:$A$504,A20)=0,"BELUM LENGKAP",INDEX('RINGKASAN STOK'!$J$5:$J$504,MATCH(A20,'RINGKASAN STOK'!$A$5:$A$504,0))))
I21: =IF(A21="","",IF(OR(NOT(ISNUMBER(G21)),NOT(ISNUMBER(H21)),H21<=0),"BELUM LENGKAP",ROUND(G21/H21,4))) | K21: =IF(A21="","",IF(COUNTIFS('RINGKASAN STOK'!$A$5:$A$504,A21)=0,"BELUM LENGKAP",INDEX('RINGKASAN STOK'!$J$5:$J$504,MATCH(A21,'RINGKASAN STOK'!$A$5:$A$504,0))))
I22: =IF(A22="","",IF(OR(NOT(ISNUMBER(G22)),NOT(ISNUMBER(H22)),H22<=0),"BELUM LENGKAP",ROUND(G22/H22,4))) | K22: =IF(A22="","",IF(COUNTIFS('RINGKASAN STOK'!$A$5:$A$504,A22)=0,"BELUM LENGKAP",INDEX('RINGKASAN STOK'!$J$5:$J$504,MATCH(A22,'RINGKASAN STOK'!$A$5:$A$504,0))))
I23: =IF(A23="","",IF(OR(NOT(ISNUMBER(G23)),NOT(ISNUMBER(H23)),H23<=0),"BELUM LENGKAP",ROUND(G23/H23,4))) | K23: =IF(A23="","",IF(COUNTIFS('RINGKASAN STOK'!$A$5:$A$504,A23)=0,"BELUM LENGKAP",INDEX('RINGKASAN STOK'!$J$5:$J$504,MATCH(A23,'RINGKASAN STOK'!$A$5:$A$504,0))))
I24: =IF(A24="","",IF(OR(NOT(ISNUMBER(G24)),NOT(ISNUMBER(H24)),H24<=0),"BELUM LENGKAP",ROUND(G24/H24,4))) | K24: =IF(A24="","",IF(COUNTIFS('RINGKASAN STOK'!$A$5:$A$504,A24)=0,"BELUM LENGKAP",INDEX('RINGKASAN STOK'!$J$5:$J$504,MATCH(A24,'RINGKASAN STOK'!$A$5:$A$504,0))))
I25: =IF(A25="","",IF(OR(NOT(ISNUMBER(G25)),NOT(ISNUMBER(H25)),H25<=0),"BELUM LENGKAP",ROUND(G25/H25,4))) | K25: =IF(A25="","",IF(COUNTIFS('RINGKASAN STOK'!$A$5:$A$504,A25)=0,"BELUM LENGKAP",INDEX('RINGKASAN STOK'!$J$5:$J$504,MATCH(A25,'RINGKASAN STOK'!$A$5:$A$504,0))))
I26: =IF(A26="","",IF(OR(NOT(ISNUMBER(G26)),NOT(ISNUMBER(H26)),H26<=0),"BELUM LENGKAP",ROUND(G26/H26,4))) | K26: =IF(A26="","",IF(COUNTIFS('RINGKASAN STOK'!$A$5:$A$504,A26)=0,"BELUM LENGKAP",INDEX('RINGKASAN STOK'!$J$5:$J$504,MATCH(A26,'RINGKASAN STOK'!$A$5:$A$504,0))))
I27: =IF(A27="","",IF(OR(NOT(ISNUMBER(G27)),NOT(ISNUMBER(H27)),H27<=0),"BELUM LENGKAP",ROUND(G27/H27,4))) | K27: =IF(A27="","",IF(COUNTIFS('RINGKASAN STOK'!$A$5:$A$504,A27)=0,"BELUM LENGKAP",INDEX('RINGKASAN STOK'!$J$5:$J$504,MATCH(A27,'RINGKASAN STOK'!$A$5:$A$504,0))))
I28: =IF(A28="","",IF(OR(NOT(ISNUMBER(G28)),NOT(ISNUMBER(H28)),H28<=0),"BELUM LENGKAP",ROUND(G28/H28,4))) | K28: =IF(A28="","",IF(COUNTIFS('RINGKASAN STOK'!$A$5:$A$504,A28)=0,"BELUM LENGKAP",INDEX('RINGKASAN STOK'!$J$5:$J$504,MATCH(A28,'RINGKASAN STOK'!$A$5:$A$504,0))))
... I64: =IF(A64="","",IF(OR(NOT(ISNUMBER(G64)),NOT(ISNUMBER(H64)),H64<=0),"BELUM LENGKAP",ROUND(G64/H64,4))) | K64: =IF(A64="","",IF(COUNTIFS('RINGKASAN STOK'!$A$5:$A$504,A64)=0,"BELUM LENGKAP",INDEX('RINGKASAN STOK'!$J$5:$J$504,MATCH(A64,'RINGKASAN STOK'!$A$5:$A$504,0))))

Sheet RESEP DAN HPP
A1: RESEP DAN HPP
A2: Satu baris per bahan. Total HPP diulang pada baris resep yang sama agar mudah difilter.
A3: ISI MANUAL | B3: HASIL OTOMATIS | C3: ID CONTOH- = simulasi
A4: ID menu | B4: Nama menu | C4: Varian | D4: ID bahan | E4: Nama bahan | F4: Jumlah / porsi | G4: Satuan | H4: Biaya / satuan | I4: Biaya bahan / porsi | J4: Total HPP menu | K4: Harga jual | L4: Laba kotor | M4: Margin | N4: Status kelengkapan HPP
A5: CONTOH-M01 | B5: =IF(A5="","",IF(COUNTIFS('MASTER MENU'!$A$5:$A$504,A5)=0,"BELUM ADA",INDEX('MASTER MENU'!$B$5:$B$504,MATCH(A5,'MASTER MENU'!$A$5:$A$504,0)))) -> Kopi Susu Gula Aren | C5: =IF(A5="","",IF(COUNTIFS('MASTER MENU'!$A$5:$A$504,A5)=0,"BELUM ADA",INDEX('MASTER MENU'!$E$5:$E$504,MATCH(A5,'MASTER MENU'!$A$5:$A$504,0)))) -> Reguler | D5: CONTOH-B01 | E5: =IF(D5="","",IF(COUNTIFS('MASTER BAHAN'!$A$5:$A$504,D5)=0,"BELUM ADA",INDEX('MASTER BAHAN'!$B$5:$B$504,MATCH(D5,'MASTER BAHAN'!$A$5:$A$504,0)))) -> Biji kopi | F5: 18 | G5: =IF(D5="","",IF(COUNTIFS('MASTER BAHAN'!$A$5:$A$504,D5)=0,"BELUM ADA",INDEX('MASTER BAHAN'!$D$5:$D$504,MATCH(D5,'MASTER BAHAN'!$A$5:$A$504,0)))) -> gram | H5: =IF(D5="","",IF(COUNTIFS('MASTER BAHAN'!$A$5:$A$504,D5)=0,"BELUM ADA",INDEX('MASTER BAHAN'!$I$5:$I$504,MATCH(D5,'MASTER BAHAN'!$A$5:$A$504,0)))) -> 150 | I5: =IF(A5="","",IF(OR(NOT(ISNUMBER(F5)),NOT(ISNUMBER(H5))),"BELUM LENGKAP",ROUND(F5*H5,0))) -> 2700 | J5: =IF(A5="","",IF(COUNTIFS($A$5:$A$504,A5,$N$5:$N$504,"BELUM LENGKAP")>0,"BELUM LENGKAP",SUMIFS($I$5:$I$504,$A$5:$A$504,A5))) -> 7300 | K5: =IF(A5="","",IF(COUNTIFS('MASTER MENU'!$A$5:$A$504,A5)=0,"BELUM ADA",INDEX('MASTER MENU'!$F$5:$F$504,MATCH(A5,'MASTER MENU'!$A$5:$A$504,0)))) -> 28000 | L5: =IF(A5="","",IF(OR(NOT(ISNUMBER(J5)),NOT(ISNUMBER(K5))),"BELUM LENGKAP",K5-J5)) -> 20700 | M5: =IF(A5="","",IF(OR(NOT(ISNUMBER(L5)),K5=0),"BELUM LENGKAP",L5/K5)) -> 0.73928571 | N5: =IF(A5="","",IF(OR(B5="BELUM ADA",E5="BELUM ADA",NOT(ISNUMBER(F5)),F5<=0,NOT(ISNUMBER(H5)),NOT(ISNUMBER(K5))),"BELUM LENGKAP","LENGKAP")) -> LENGKAP
A6: CONTOH-M01 | B6: =IF(A6="","",IF(COUNTIFS('MASTER MENU'!$A$5:$A$504,A6)=0,"BELUM ADA",INDEX('MASTER MENU'!$B$5:$B$504,MATCH(A6,'MASTER MENU'!$A$5:$A$504,0)))) -> Kopi Susu Gula Aren | C6: =IF(A6="","",IF(COUNTIFS('MASTER MENU'!$A$5:$A$504,A6)=0,"BELUM ADA",INDEX('MASTER MENU'!$E$5:$E$504,MATCH(A6,'MASTER MENU'!$A$5:$A$504,0)))) -> Reguler | D6: CONTOH-B02 | E6: =IF(D6="","",IF(COUNTIFS('MASTER BAHAN'!$A$5:$A$504,D6)=0,"BELUM ADA",INDEX('MASTER BAHAN'!$B$5:$B$504,MATCH(D6,'MASTER BAHAN'!$A$5:$A$504,0)))) -> Susu UHT | F6: 150 | G6: =IF(D6="","",IF(COUNTIFS('MASTER BAHAN'!$A$5:$A$504,D6)=0,"BELUM ADA",INDEX('MASTER BAHAN'!$D$5:$D$504,MATCH(D6,'MASTER BAHAN'!$A$5:$A$504,0)))) -> ml | H6: =IF(D6="","",IF(COUNTIFS('MASTER BAHAN'!$A$5:$A$504,D6)=0,"BELUM ADA",INDEX('MASTER BAHAN'!$I$5:$I$504,MATCH(D6,'MASTER BAHAN'!$A$5:$A$504,0)))) -> 24 | I6: =IF(A6="","",IF(OR(NOT(ISNUMBER(F6)),NOT(ISNUMBER(H6))),"BELUM LENGKAP",ROUND(F6*H6,0))) -> 3600 | J6: =IF(A6="","",IF(COUNTIFS($A$5:$A$504,A6,$N$5:$N$504,"BELUM LENGKAP")>0,"BELUM LENGKAP",SUMIFS($I$5:$I$504,$A$5:$A$504,A6))) -> 7300 | K6: =IF(A6="","",IF(COUNTIFS('MASTER MENU'!$A$5:$A$504,A6)=0,"BELUM ADA",INDEX('MASTER MENU'!$F$5:$F$504,MATCH(A6,'MASTER MENU'!$A$5:$A$504,0)))) -> 28000 | L6: =IF(A6="","",IF(OR(NOT(ISNUMBER(J6)),NOT(ISNUMBER(K6))),"BELUM LENGKAP",K6-J6)) -> 20700 | M6: =IF(A6="","",IF(OR(NOT(ISNUMBER(L6)),K6=0),"BELUM LENGKAP",L6/K6)) -> 0.73928571 | N6: =IF(A6="","",IF(OR(B6="BELUM ADA",E6="BELUM ADA",NOT(ISNUMBER(F6)),F6<=0,NOT(ISNUMBER(H6)),NOT(ISNUMBER(K6))),"BELUM LENGKAP","LENGKAP")) -> LENGKAP
A7: CONTOH-M01 | B7: =IF(A7="","",IF(COUNTIFS('MASTER MENU'!$A$5:$A$504,A7)=0,"BELUM ADA",INDEX('MASTER MENU'!$B$5:$B$504,MATCH(A7,'MASTER MENU'!$A$5:$A$504,0)))) -> Kopi Susu Gula Aren | C7: =IF(A7="","",IF(COUNTIFS('MASTER MENU'!$A$5:$A$504,A7)=0,"BELUM ADA",INDEX('MASTER MENU'!$E$5:$E$504,MATCH(A7,'MASTER MENU'!$A$5:$A$504,0)))) -> Reguler | D7: CONTOH-B03 | E7: =IF(D7="","",IF(COUNTIFS('MASTER BAHAN'!$A$5:$A$504,D7)=0,"BELUM ADA",INDEX('MASTER BAHAN'!$B$5:$B$504,MATCH(D7,'MASTER BAHAN'!$A$5:$A$504,0)))) -> Gula aren | F7: 25 | G7: =IF(D7="","",IF(COUNTIFS('MASTER BAHAN'!$A$5:$A$504,D7)=0,"BELUM ADA",INDEX('MASTER BAHAN'!$D$5:$D$504,MATCH(D7,'MASTER BAHAN'!$A$5:$A$504,0)))) -> ml | H7: =IF(D7="","",IF(COUNTIFS('MASTER BAHAN'!$A$5:$A$504,D7)=0,"BELUM ADA",INDEX('MASTER BAHAN'!$I$5:$I$504,MATCH(D7,'MASTER BAHAN'!$A$5:$A$504,0)))) -> 40 | I7: =IF(A7="","",IF(OR(NOT(ISNUMBER(F7)),NOT(ISNUMBER(H7))),"BELUM LENGKAP",ROUND(F7*H7,0))) -> 1000 | J7: =IF(A7="","",IF(COUNTIFS($A$5:$A$504,A7,$N$5:$N$504,"BELUM LENGKAP")>0,"BELUM LENGKAP",SUMIFS($I$5:$I$504,$A$5:$A$504,A7))) -> 7300 | K7: =IF(A7="","",IF(COUNTIFS('MASTER MENU'!$A$5:$A$504,A7)=0,"BELUM ADA",INDEX('MASTER MENU'!$F$5:$F$504,MATCH(A7,'MASTER MENU'!$A$5:$A$504,0)))) -> 28000 | L7: =IF(A7="","",IF(OR(NOT(ISNUMBER(J7)),NOT(ISNUMBER(K7))),"BELUM LENGKAP",K7-J7)) -> 20700 | M7: =IF(A7="","",IF(OR(NOT(ISNUMBER(L7)),K7=0),"BELUM LENGKAP",L7/K7)) -> 0.73928571 | N7: =IF(A7="","",IF(OR(B7="BELUM ADA",E7="BELUM ADA",NOT(ISNUMBER(F7)),F7<=0,NOT(ISNUMBER(H7)),NOT(ISNUMBER(K7))),"BELUM LENGKAP","LENGKAP")) -> LENGKAP
A8: CONTOH-M02 | B8: =IF(A8="","",IF(COUNTIFS('MASTER MENU'!$A$5:$A$504,A8)=0,"BELUM ADA",INDEX('MASTER MENU'!$B$5:$B$504,MATCH(A8,'MASTER MENU'!$A$5:$A$504,0)))) -> Americano | C8: =IF(A8="","",IF(COUNTIFS('MASTER MENU'!$A$5:$A$504,A8)=0,"BELUM ADA",INDEX('MASTER MENU'!$E$5:$E$504,MATCH(A8,'MASTER MENU'!$A$5:$A$504,0)))) -> Ice | D8: CONTOH-B01 | E8: =IF(D8="","",IF(COUNTIFS('MASTER BAHAN'!$A$5:$A$504,D8)=0,"BELUM ADA",INDEX('MASTER BAHAN'!$B$5:$B$504,MATCH(D8,'MASTER BAHAN'!$A$5:$A$504,0)))) -> Biji kopi | F8: 20 | G8: =IF(D8="","",IF(COUNTIFS('MASTER BAHAN'!$A$5:$A$504,D8)=0,"BELUM ADA",INDEX('MASTER BAHAN'!$D$5:$D$504,MATCH(D8,'MASTER BAHAN'!$A$5:$A$504,0)))) -> gram | H8: =IF(D8="","",IF(COUNTIFS('MASTER BAHAN'!$A$5:$A$504,D8)=0,"BELUM ADA",INDEX('MASTER BAHAN'!$I$5:$I$504,MATCH(D8,'MASTER BAHAN'!$A$5:$A$504,0)))) -> 150 | I8: =IF(A8="","",IF(OR(NOT(ISNUMBER(F8)),NOT(ISNUMBER(H8))),"BELUM LENGKAP",ROUND(F8*H8,0))) -> 3000 | J8: =IF(A8="","",IF(COUNTIFS($A$5:$A$504,A8,$N$5:$N$504,"BELUM LENGKAP")>0,"BELUM LENGKAP",SUMIFS($I$5:$I$504,$A$5:$A$504,A8))) -> 3160 | K8: =IF(A8="","",IF(COUNTIFS('MASTER MENU'!$A$5:$A$504,A8)=0,"BELUM ADA",INDEX('MASTER MENU'!$F$5:$F$504,MATCH(A8,'MASTER MENU'!$A$5:$A$504,0)))) -> 25000 | L8: =IF(A8="","",IF(OR(NOT(ISNUMBER(J8)),NOT(ISNUMBER(K8))),"BELUM LENGKAP",K8-J8)) -> 21840 | M8: =IF(A8="","",IF(OR(NOT(ISNUMBER(L8)),K8=0),"BELUM LENGKAP",L8/K8)) -> 0.8736 | N8: =IF(A8="","",IF(OR(B8="BELUM ADA",E8="BELUM ADA",NOT(ISNUMBER(F8)),F8<=0,NOT(ISNUMBER(H8)),NOT(ISNUMBER(K8))),"BELUM LENGKAP","LENGKAP")) -> LENGKAP
A9: CONTOH-M02 | B9: =IF(A9="","",IF(COUNTIFS('MASTER MENU'!$A$5:$A$504,A9)=0,"BELUM ADA",INDEX('MASTER MENU'!$B$5:$B$504,MATCH(A9,'MASTER MENU'!$A$5:$A$504,0)))) -> Americano | C9: =IF(A9="","",IF(COUNTIFS('MASTER MENU'!$A$5:$A$504,A9)=0,"BELUM ADA",INDEX('MASTER MENU'!$E$5:$E$504,MATCH(A9,'MASTER MENU'!$A$5:$A$504,0)))) -> Ice | D9: CONTOH-B04 | E9: =IF(D9="","",IF(COUNTIFS('MASTER BAHAN'!$A$5:$A$504,D9)=0,"BELUM ADA",INDEX('MASTER BAHAN'!$B$5:$B$504,MATCH(D9,'MASTER BAHAN'!$A$5:$A$504,0)))) -> Air mineral | F9: 200 | G9: =IF(D9="","",IF(COUNTIFS('MASTER BAHAN'!$A$5:$A$504,D9)=0,"BELUM ADA",INDEX('MASTER BAHAN'!$D$5:$D$504,MATCH(D9,'MASTER BAHAN'!$A$5:$A$504,0)))) -> ml | H9: =IF(D9="","",IF(COUNTIFS('MASTER BAHAN'!$A$5:$A$504,D9)=0,"BELUM ADA",INDEX('MASTER BAHAN'!$I$5:$I$504,MATCH(D9,'MASTER BAHAN'!$A$5:$A$504,0)))) -> 0.8 | I9: =IF(A9="","",IF(OR(NOT(ISNUMBER(F9)),NOT(ISNUMBER(H9))),"BELUM LENGKAP",ROUND(F9*H9,0))) -> 160 | J9: =IF(A9="","",IF(COUNTIFS($A$5:$A$504,A9,$N$5:$N$504,"BELUM LENGKAP")>0,"BELUM LENGKAP",SUMIFS($I$5:$I$504,$A$5:$A$504,A9))) -> 3160 | K9: =IF(A9="","",IF(COUNTIFS('MASTER MENU'!$A$5:$A$504,A9)=0,"BELUM ADA",INDEX('MASTER MENU'!$F$5:$F$504,MATCH(A9,'MASTER MENU'!$A$5:$A$504,0)))) -> 25000 | L9: =IF(A9="","",IF(OR(NOT(ISNUMBER(J9)),NOT(ISNUMBER(K9))),"BELUM LENGKAP",K9-J9)) -> 21840 | M9: =IF(A9="","",IF(OR(NOT(ISNUMBER(L9)),K9=0),"BELUM LENGKAP",L9/K9)) -> 0.8736 | N9: =IF(A9="","",IF(OR(B9="BELUM ADA",E9="BELUM ADA",NOT(ISNUMBER(F9)),F9<=0,NOT(ISNUMBER(H9)),NOT(ISNUMBER(K9))),"BELUM LENGKAP","LENGKAP")) -> LENGKAP
A10: CONTOH-M03 | B10: =IF(A10="","",IF(COUNTIFS('MASTER MENU'!$A$5:$A$504,A10)=0,"BELUM ADA",INDEX('MASTER MENU'!$B$5:$B$504,MATCH(A10,'MASTER MENU'!$A$5:$A$504,0)))) -> Latte | C10: =IF(A10="","",IF(COUNTIFS('MASTER MENU'!$A$5:$A$504,A10)=0,"BELUM ADA",INDEX('MASTER MENU'!$E$5:$E$504,MATCH(A10,'MASTER MENU'!$A$5:$A$504,0)))) -> Hot | D10: CONTOH-B01 | E10: =IF(D10="","",IF(COUNTIFS('MASTER BAHAN'!$A$5:$A$504,D10)=0,"BELUM ADA",INDEX('MASTER BAHAN'!$B$5:$B$504,MATCH(D10,'MASTER BAHAN'!$A$5:$A$504,0)))) -> Biji kopi | F10: 18 | G10: =IF(D10="","",IF(COUNTIFS('MASTER BAHAN'!$A$5:$A$504,D10)=0,"BELUM ADA",INDEX('MASTER BAHAN'!$D$5:$D$504,MATCH(D10,'MASTER BAHAN'!$A$5:$A$504,0)))) -> gram | H10: =IF(D10="","",IF(COUNTIFS('MASTER BAHAN'!$A$5:$A$504,D10)=0,"BELUM ADA",INDEX('MASTER BAHAN'!$I$5:$I$504,MATCH(D10,'MASTER BAHAN'!$A$5:$A$504,0)))) -> 150 | I10: =IF(A10="","",IF(OR(NOT(ISNUMBER(F10)),NOT(ISNUMBER(H10))),"BELUM LENGKAP",ROUND(F10*H10,0))) -> 2700 | J10: =IF(A10="","",IF(COUNTIFS($A$5:$A$504,A10,$N$5:$N$504,"BELUM LENGKAP")>0,"BELUM LENGKAP",SUMIFS($I$5:$I$504,$A$5:$A$504,A10))) -> 7020 | K10: =IF(A10="","",IF(COUNTIFS('MASTER MENU'!$A$5:$A$504,A10)=0,"BELUM ADA",INDEX('MASTER MENU'!$F$5:$F$504,MATCH(A10,'MASTER MENU'!$A$5:$A$504,0)))) -> 32000 | L10: =IF(A10="","",IF(OR(NOT(ISNUMBER(J10)),NOT(ISNUMBER(K10))),"BELUM LENGKAP",K10-J10)) -> 24980 | M10: =IF(A10="","",IF(OR(NOT(ISNUMBER(L10)),K10=0),"BELUM LENGKAP",L10/K10)) -> 0.780625 | N10: =IF(A10="","",IF(OR(B10="BELUM ADA",E10="BELUM ADA",NOT(ISNUMBER(F10)),F10<=0,NOT(ISNUMBER(H10)),NOT(ISNUMBER(K10))),"BELUM LENGKAP","LENGKAP")) -> LENGKAP
A11: CONTOH-M03 | B11: =IF(A11="","",IF(COUNTIFS('MASTER MENU'!$A$5:$A$504,A11)=0,"BELUM ADA",INDEX('MASTER MENU'!$B$5:$B$504,MATCH(A11,'MASTER MENU'!$A$5:$A$504,0)))) -> Latte | C11: =IF(A11="","",IF(COUNTIFS('MASTER MENU'!$A$5:$A$504,A11)=0,"BELUM ADA",INDEX('MASTER MENU'!$E$5:$E$504,MATCH(A11,'MASTER MENU'!$A$5:$A$504,0)))) -> Hot | D11: CONTOH-B02 | E11: =IF(D11="","",IF(COUNTIFS('MASTER BAHAN'!$A$5:$A$504,D11)=0,"BELUM ADA",INDEX('MASTER BAHAN'!$B$5:$B$504,MATCH(D11,'MASTER BAHAN'!$A$5:$A$504,0)))) -> Susu UHT | F11: 180 | G11: =IF(D11="","",IF(COUNTIFS('MASTER BAHAN'!$A$5:$A$504,D11)=0,"BELUM ADA",INDEX('MASTER BAHAN'!$D$5:$D$504,MATCH(D11,'MASTER BAHAN'!$A$5:$A$504,0)))) -> ml | H11: =IF(D11="","",IF(COUNTIFS('MASTER BAHAN'!$A$5:$A$504,D11)=0,"BELUM ADA",INDEX('MASTER BAHAN'!$I$5:$I$504,MATCH(D11,'MASTER BAHAN'!$A$5:$A$504,0)))) -> 24 | I11: =IF(A11="","",IF(OR(NOT(ISNUMBER(F11)),NOT(ISNUMBER(H11))),"BELUM LENGKAP",ROUND(F11*H11,0))) -> 4320 | J11: =IF(A11="","",IF(COUNTIFS($A$5:$A$504,A11,$N$5:$N$504,"BELUM LENGKAP")>0,"BELUM LENGKAP",SUMIFS($I$5:$I$504,$A$5:$A$504,A11))) -> 7020 | K11: =IF(A11="","",IF(COUNTIFS('MASTER MENU'!$A$5:$A$504,A11)=0,"BELUM ADA",INDEX('MASTER MENU'!$F$5:$F$504,MATCH(A11,'MASTER MENU'!$A$5:$A$504,0)))) -> 32000 | L11: =IF(A11="","",IF(OR(NOT(ISNUMBER(J11)),NOT(ISNUMBER(K11))),"BELUM LENGKAP",K11-J11)) -> 24980 | M11: =IF(A11="","",IF(OR(NOT(ISNUMBER(L11)),K11=0),"BELUM LENGKAP",L11/K11)) -> 0.780625 | N11: =IF(A11="","",IF(OR(B11="BELUM ADA",E11="BELUM ADA",NOT(ISNUMBER(F11)),F11<=0,NOT(ISNUMBER(H11)),NOT(ISNUMBER(K11))),"BELUM LENGKAP","LENGKAP")) -> LENGKAP
A12: CONTOH-M04 | B12: =IF(A12="","",IF(COUNTIFS('MASTER MENU'!$A$5:$A$504,A12)=0,"BELUM ADA",INDEX('MASTER MENU'!$B$5:$B$504,MATCH(A12,'MASTER MENU'!$A$5:$A$504,0)))) -> Matcha Latte | C12: =IF(A12="","",IF(COUNTIFS('MASTER MENU'!$A$5:$A$504,A12)=0,"BELUM ADA",INDEX('MASTER MENU'!$E$5:$E$504,MATCH(A12,'MASTER MENU'!$A$5:$A$504,0)))) -> Ice | D12: CONTOH-B05 | E12: =IF(D12="","",IF(COUNTIFS('MASTER BAHAN'!$A$5:$A$504,D12)=0,"BELUM ADA",INDEX('MASTER BAHAN'!$B$5:$B$504,MATCH(D12,'MASTER BAHAN'!$A$5:$A$504,0)))) -> Bubuk matcha | F12: 12 | G12: =IF(D12="","",IF(COUNTIFS('MASTER BAHAN'!$A$5:$A$504,D12)=0,"BELUM ADA",INDEX('MASTER BAHAN'!$D$5:$D$504,MATCH(D12,'MASTER BAHAN'!$A$5:$A$504,0)))) -> gram | H12: =IF(D12="","",IF(COUNTIFS('MASTER BAHAN'!$A$5:$A$504,D12)=0,"BELUM ADA",INDEX('MASTER BAHAN'!$I$5:$I$504,MATCH(D12,'MASTER BAHAN'!$A$5:$A$504,0)))) -> 220 | I12: =IF(A12="","",IF(OR(NOT(ISNUMBER(F12)),NOT(ISNUMBER(H12))),"BELUM LENGKAP",ROUND(F12*H12,0))) -> 2640 | J12: =IF(A12="","",IF(COUNTIFS($A$5:$A$504,A12,$N$5:$N$504,"BELUM LENGKAP")>0,"BELUM LENGKAP",SUMIFS($I$5:$I$504,$A$5:$A$504,A12))) -> 6960 | K12: =IF(A12="","",IF(COUNTIFS('MASTER MENU'!$A$5:$A$504,A12)=0,"BELUM ADA",INDEX('MASTER MENU'!$F$5:$F$504,MATCH(A12,'MASTER MENU'!$A$5:$A$504,0)))) -> 33000 | L12: =IF(A12="","",IF(OR(NOT(ISNUMBER(J12)),NOT(ISNUMBER(K12))),"BELUM LENGKAP",K12-J12)) -> 26040 | M12: =IF(A12="","",IF(OR(NOT(ISNUMBER(L12)),K12=0),"BELUM LENGKAP",L12/K12)) -> 0.78909091 | N12: =IF(A12="","",IF(OR(B12="BELUM ADA",E12="BELUM ADA",NOT(ISNUMBER(F12)),F12<=0,NOT(ISNUMBER(H12)),NOT(ISNUMBER(K12))),"BELUM LENGKAP","LENGKAP")) -> LENGKAP
A13: CONTOH-M04 | B13: =IF(A13="","",IF(COUNTIFS('MASTER MENU'!$A$5:$A$504,A13)=0,"BELUM ADA",INDEX('MASTER MENU'!$B$5:$B$504,MATCH(A13,'MASTER MENU'!$A$5:$A$504,0)))) -> Matcha Latte | C13: =IF(A13="","",IF(COUNTIFS('MASTER MENU'!$A$5:$A$504,A13)=0,"BELUM ADA",INDEX('MASTER MENU'!$E$5:$E$504,MATCH(A13,'MASTER MENU'!$A$5:$A$504,0)))) -> Ice | D13: CONTOH-B02 | E13: =IF(D13="","",IF(COUNTIFS('MASTER BAHAN'!$A$5:$A$504,D13)=0,"BELUM ADA",INDEX('MASTER BAHAN'!$B$5:$B$504,MATCH(D13,'MASTER BAHAN'!$A$5:$A$504,0)))) -> Susu UHT | F13: 180 | G13: =IF(D13="","",IF(COUNTIFS('MASTER BAHAN'!$A$5:$A$504,D13)=0,"BELUM ADA",INDEX('MASTER BAHAN'!$D$5:$D$504,MATCH(D13,'MASTER BAHAN'!$A$5:$A$504,0)))) -> ml | H13: =IF(D13="","",IF(COUNTIFS('MASTER BAHAN'!$A$5:$A$504,D13)=0,"BELUM ADA",INDEX('MASTER BAHAN'!$I$5:$I$504,MATCH(D13,'MASTER BAHAN'!$A$5:$A$504,0)))) -> 24 | I13: =IF(A13="","",IF(OR(NOT(ISNUMBER(F13)),NOT(ISNUMBER(H13))),"BELUM LENGKAP",ROUND(F13*H13,0))) -> 4320 | J13: =IF(A13="","",IF(COUNTIFS($A$5:$A$504,A13,$N$5:$N$504,"BELUM LENGKAP")>0,"BELUM LENGKAP",SUMIFS($I$5:$I$504,$A$5:$A$504,A13))) -> 6960 | K13: =IF(A13="","",IF(COUNTIFS('MASTER MENU'!$A$5:$A$504,A13)=0,"BELUM ADA",INDEX('MASTER MENU'!$F$5:$F$504,MATCH(A13,'MASTER MENU'!$A$5:$A$504,0)))) -> 33000 | L13: =IF(A13="","",IF(OR(NOT(ISNUMBER(J13)),NOT(ISNUMBER(K13))),"BELUM LENGKAP",K13-J13)) -> 26040 | M13: =IF(A13="","",IF(OR(NOT(ISNUMBER(L13)),K13=0),"BELUM LENGKAP",L13/K13)) -> 0.78909091 | N13: =IF(A13="","",IF(OR(B13="BELUM ADA",E13="BELUM ADA",NOT(ISNUMBER(F13)),F13<=0,NOT(ISNUMBER(H13)),NOT(ISNUMBER(K13))),"BELUM LENGKAP","LENGKAP")) -> LENGKAP
A14: CONTOH-M05 | B14: =IF(A14="","",IF(COUNTIFS('MASTER MENU'!$A$5:$A$504,A14)=0,"BELUM ADA",INDEX('MASTER MENU'!$B$5:$B$504,MATCH(A14,'MASTER MENU'!$A$5:$A$504,0)))) -> Teh Lemon | C14: =IF(A14="","",IF(COUNTIFS('MASTER MENU'!$A$5:$A$504,A14)=0,"BELUM ADA",INDEX('MASTER MENU'!$E$5:$E$504,MATCH(A14,'MASTER MENU'!$A$5:$A$504,0)))) -> Ice | D14: CONTOH-B06 | E14: =IF(D14="","",IF(COUNTIFS('MASTER BAHAN'!$A$5:$A$504,D14)=0,"BELUM ADA",INDEX('MASTER BAHAN'!$B$5:$B$504,MATCH(D14,'MASTER BAHAN'!$A$5:$A$504,0)))) -> Teh celup | F14: 1 | G14: =IF(D14="","",IF(COUNTIFS('MASTER BAHAN'!$A$5:$A$504,D14)=0,"BELUM ADA",INDEX('MASTER BAHAN'!$D$5:$D$504,MATCH(D14,'MASTER BAHAN'!$A$5:$A$504,0)))) -> pcs | H14: =IF(D14="","",IF(COUNTIFS('MASTER BAHAN'!$A$5:$A$504,D14)=0,"BELUM ADA",INDEX('MASTER BAHAN'!$I$5:$I$504,MATCH(D14,'MASTER BAHAN'!$A$5:$A$504,0)))) -> 400 | I14: =IF(A14="","",IF(OR(NOT(ISNUMBER(F14)),NOT(ISNUMBER(H14))),"BELUM LENGKAP",ROUND(F14*H14,0))) -> 400 | J14: =IF(A14="","",IF(COUNTIFS($A$5:$A$504,A14,$N$5:$N$504,"BELUM LENGKAP")>0,"BELUM LENGKAP",SUMIFS($I$5:$I$504,$A$5:$A$504,A14))) -> 1300 | K14: =IF(A14="","",IF(COUNTIFS('MASTER MENU'!$A$5:$A$504,A14)=0,"BELUM ADA",INDEX('MASTER MENU'!$F$5:$F$504,MATCH(A14,'MASTER MENU'!$A$5:$A$504,0)))) -> 22000 | L14: =IF(A14="","",IF(OR(NOT(ISNUMBER(J14)),NOT(ISNUMBER(K14))),"BELUM LENGKAP",K14-J14)) -> 20700 | M14: =IF(A14="","",IF(OR(NOT(ISNUMBER(L14)),K14=0),"BELUM LENGKAP",L14/K14)) -> 0.94090909 | N14: =IF(A14="","",IF(OR(B14="BELUM ADA",E14="BELUM ADA",NOT(ISNUMBER(F14)),F14<=0,NOT(ISNUMBER(H14)),NOT(ISNUMBER(K14))),"BELUM LENGKAP","LENGKAP")) -> LENGKAP
A15: CONTOH-M05 | B15: =IF(A15="","",IF(COUNTIFS('MASTER MENU'!$A$5:$A$504,A15)=0,"BELUM ADA",INDEX('MASTER MENU'!$B$5:$B$504,MATCH(A15,'MASTER MENU'!$A$5:$A$504,0)))) -> Teh Lemon | C15: =IF(A15="","",IF(COUNTIFS('MASTER MENU'!$A$5:$A$504,A15)=0,"BELUM ADA",INDEX('MASTER MENU'!$E$5:$E$504,MATCH(A15,'MASTER MENU'!$A$5:$A$504,0)))) -> Ice | D15: CONTOH-B07 | E15: =IF(D15="","",IF(COUNTIFS('MASTER BAHAN'!$A$5:$A$504,D15)=0,"BELUM ADA",INDEX('MASTER BAHAN'!$B$5:$B$504,MATCH(D15,'MASTER BAHAN'!$A$5:$A$504,0)))) -> Lemon | F15: 30 | G15: =IF(D15="","",IF(COUNTIFS('MASTER BAHAN'!$A$5:$A$504,D15)=0,"BELUM ADA",INDEX('MASTER BAHAN'!$D$5:$D$504,MATCH(D15,'MASTER BAHAN'!$A$5:$A$504,0)))) -> gram | H15: =IF(D15="","",IF(COUNTIFS('MASTER BAHAN'!$A$5:$A$504,D15)=0,"BELUM ADA",INDEX('MASTER BAHAN'!$I$5:$I$504,MATCH(D15,'MASTER BAHAN'!$A$5:$A$504,0)))) -> 30 | I15: =IF(A15="","",IF(OR(NOT(ISNUMBER(F15)),NOT(ISNUMBER(H15))),"BELUM LENGKAP",ROUND(F15*H15,0))) -> 900 | J15: =IF(A15="","",IF(COUNTIFS($A$5:$A$504,A15,$N$5:$N$504,"BELUM LENGKAP")>0,"BELUM LENGKAP",SUMIFS($I$5:$I$504,$A$5:$A$504,A15))) -> 1300 | K15: =IF(A15="","",IF(COUNTIFS('MASTER MENU'!$A$5:$A$504,A15)=0,"BELUM ADA",INDEX('MASTER MENU'!$F$5:$F$504,MATCH(A15,'MASTER MENU'!$A$5:$A$504,0)))) -> 22000 | L15: =IF(A15="","",IF(OR(NOT(ISNUMBER(J15)),NOT(ISNUMBER(K15))),"BELUM LENGKAP",K15-J15)) -> 20700 | M15: =IF(A15="","",IF(OR(NOT(ISNUMBER(L15)),K15=0),"BELUM LENGKAP",L15/K15)) -> 0.94090909 | N15: =IF(A15="","",IF(OR(B15="BELUM ADA",E15="BELUM ADA",NOT(ISNUMBER(F15)),F15<=0,NOT(ISNUMBER(H15)),NOT(ISNUMBER(K15))),"BELUM LENGKAP","LENGKAP")) -> LENGKAP
A16: CONTOH-M06 | B16: =IF(A16="","",IF(COUNTIFS('MASTER MENU'!$A$5:$A$504,A16)=0,"BELUM ADA",INDEX('MASTER MENU'!$B$5:$B$504,MATCH(A16,'MASTER MENU'!$A$5:$A$504,0)))) -> Croissant Butter | C16: =IF(A16="","",IF(COUNTIFS('MASTER MENU'!$A$5:$A$504,A16)=0,"BELUM ADA",INDEX('MASTER MENU'!$E$5:$E$504,MATCH(A16,'MASTER MENU'!$A$5:$A$504,0)))) -> Reguler | D16: CONTOH-B08 | E16: =IF(D16="","",IF(COUNTIFS('MASTER BAHAN'!$A$5:$A$504,D16)=0,"BELUM ADA",INDEX('MASTER BAHAN'!$B$5:$B$504,MATCH(D16,'MASTER BAHAN'!$A$5:$A$504,0)))) -> Croissant beku | F16: 1 | G16: =IF(D16="","",IF(COUNTIFS('MASTER BAHAN'!$A$5:$A$504,D16)=0,"BELUM ADA",INDEX('MASTER BAHAN'!$D$5:$D$504,MATCH(D16,'MASTER BAHAN'!$A$5:$A$504,0)))) -> pcs | H16: =IF(D16="","",IF(COUNTIFS('MASTER BAHAN'!$A$5:$A$504,D16)=0,"BELUM ADA",INDEX('MASTER BAHAN'!$I$5:$I$504,MATCH(D16,'MASTER BAHAN'!$A$5:$A$504,0)))) -> 7500 | I16: =IF(A16="","",IF(OR(NOT(ISNUMBER(F16)),NOT(ISNUMBER(H16))),"BELUM LENGKAP",ROUND(F16*H16,0))) -> 7500 | J16: =IF(A16="","",IF(COUNTIFS($A$5:$A$504,A16,$N$5:$N$504,"BELUM LENGKAP")>0,"BELUM LENGKAP",SUMIFS($I$5:$I$504,$A$5:$A$504,A16))) -> 7500 | K16: =IF(A16="","",IF(COUNTIFS('MASTER MENU'!$A$5:$A$504,A16)=0,"BELUM ADA",INDEX('MASTER MENU'!$F$5:$F$504,MATCH(A16,'MASTER MENU'!$A$5:$A$504,0)))) -> 27000 | L16: =IF(A16="","",IF(OR(NOT(ISNUMBER(J16)),NOT(ISNUMBER(K16))),"BELUM LENGKAP",K16-J16)) -> 19500 | M16: =IF(A16="","",IF(OR(NOT(ISNUMBER(L16)),K16=0),"BELUM LENGKAP",L16/K16)) -> 0.72222222 | N16: =IF(A16="","",IF(OR(B16="BELUM ADA",E16="BELUM ADA",NOT(ISNUMBER(F16)),F16<=0,NOT(ISNUMBER(H16)),NOT(ISNUMBER(K16))),"BELUM LENGKAP","LENGKAP")) -> LENGKAP
... A21: CONTOH-M10 | B21: =IF(A21="","",IF(COUNTIFS('MASTER MENU'!$A$5:$A$504,A21)=0,"BELUM ADA",INDEX('MASTER MENU'!$B$5:$B$504,MATCH(A21,'MASTER MENU'!$A$5:$A$504,0)))) -> Roti Bakar | C21: =IF(A21="","",IF(COUNTIFS('MASTER MENU'!$A$5:$A$504,A21)=0,"BELUM ADA",INDEX('MASTER MENU'!$E$5:$E$504,MATCH(A21,'MASTER MENU'!$A$5:$A$504,0)))) -> Reguler | D21: CONTOH-B12 | E21: =IF(D21="","",IF(COUNTIFS('MASTER BAHAN'!$A$5:$A$504,D21)=0,"BELUM ADA",INDEX('MASTER BAHAN'!$B$5:$B$504,MATCH(D21,'MASTER BAHAN'!$A$5:$A$504,0)))) -> Roti | F21: 2 | G21: =IF(D21="","",IF(COUNTIFS('MASTER BAHAN'!$A$5:$A$504,D21)=0,"BELUM ADA",INDEX('MASTER BAHAN'!$D$5:$D$504,MATCH(D21,'MASTER BAHAN'!$A$5:$A$504,0)))) -> pcs | H21: =IF(D21="","",IF(COUNTIFS('MASTER BAHAN'!$A$5:$A$504,D21)=0,"BELUM ADA",INDEX('MASTER BAHAN'!$I$5:$I$504,MATCH(D21,'MASTER BAHAN'!$A$5:$A$504,0)))) -> 2500 | I21: =IF(A21="","",IF(OR(NOT(ISNUMBER(F21)),NOT(ISNUMBER(H21))),"BELUM LENGKAP",ROUND(F21*H21,0))) -> 5000 | J21: =IF(A21="","",IF(COUNTIFS($A$5:$A$504,A21,$N$5:$N$504,"BELUM LENGKAP")>0,"BELUM LENGKAP",SUMIFS($I$5:$I$504,$A$5:$A$504,A21))) -> 5000 | K21: =IF(A21="","",IF(COUNTIFS('MASTER MENU'!$A$5:$A$504,A21)=0,"BELUM ADA",INDEX('MASTER MENU'!$F$5:$F$504,MATCH(A21,'MASTER MENU'!$A$5:$A$504,0)))) -> 24000 | L21: =IF(A21="","",IF(OR(NOT(ISNUMBER(J21)),NOT(ISNUMBER(K21))),"BELUM LENGKAP",K21-J21)) -> 19000 | M21: =IF(A21="","",IF(OR(NOT(ISNUMBER(L21)),K21=0),"BELUM LENGKAP",L21/K21)) -> 0.79166667 | N21: =IF(A21="","",IF(OR(B21="BELUM ADA",E21="BELUM ADA",NOT(ISNUMBER(F21)),F21<=0,NOT(ISNUMBER(H21)),NOT(ISNUMBER(K21))),"BELUM LENGKAP","LENGKAP")) -> LENGKAP
B22: =IF(A22="","",IF(COUNTIFS('MASTER MENU'!$A$5:$A$504,A22)=0,"BELUM ADA",INDEX('MASTER MENU'!$B$5:$B$504,MATCH(A22,'MASTER MENU'!$A$5:$A$504,0)))) | C22: =IF(A22="","",IF(COUNTIFS('MASTER MENU'!$A$5:$A$504,A22)=0,"BELUM ADA",INDEX('MASTER MENU'!$E$5:$E$504,MATCH(A22,'MASTER MENU'!$A$5:$A$504,0)))) | E22: =IF(D22="","",IF(COUNTIFS('MASTER BAHAN'!$A$5:$A$504,D22)=0,"BELUM ADA",INDEX('MASTER BAHAN'!$B$5:$B$504,MATCH(D22,'MASTER BAHAN'!$A$5:$A$504,0)))) | G22: =IF(D22="","",IF(COUNTIFS('MASTER BAHAN'!$A$5:$A$504,D22)=0,"BELUM ADA",INDEX('MASTER BAHAN'!$D$5:$D$504,MATCH(D22,'MASTER BAHAN'!$A$5:$A$504,0)))) | H22: =IF(D22="","",IF(COUNTIFS('MASTER BAHAN'!$A$5:$A$504,D22)=0,"BELUM ADA",INDEX('MASTER BAHAN'!$I$5:$I$504,MATCH(D22,'MASTER BAHAN'!$A$5:$A$504,0)))) | I22: =IF(A22="","",IF(OR(NOT(ISNUMBER(F22)),NOT(ISNUMBER(H22))),"BELUM LENGKAP",ROUND(F22*H22,0))) | J22: =IF(A22="","",IF(COUNTIFS($A$5:$A$504,A22,$N$5:$N$504,"BELUM LENGKAP")>0,"BELUM LENGKAP",SUMIFS($I$5:$I$504,$A$5:$A$504,A22))) | K22: =IF(A22="","",IF(COUNTIFS('MASTER MENU'!$A$5:$A$504,A22)=0,"BELUM ADA",INDEX('MASTER MENU'!$F$5:$F$504,MATCH(A22,'MASTER MENU'!$A$5:$A$504,0)))) | L22: =IF(A22="","",IF(OR(NOT(ISNUMBER(J22)),NOT(ISNUMBER(K22))),"BELUM LENGKAP",K22-J22)) | M22: =IF(A22="","",IF(OR(NOT(ISNUMBER(L22)),K22=0),"BELUM LENGKAP",L22/K22)) | N22: =IF(A22="","",IF(OR(B22="BELUM ADA",E22="BELUM ADA",NOT(ISNUMBER(F22)),F22<=0,NOT(ISNUMBER(H22)),NOT(ISNUMBER(K22))),"BELUM LENGKAP","LENGKAP"))
B23: =IF(A23="","",IF(COUNTIFS('MASTER MENU'!$A$5:$A$504,A23)=0,"BELUM ADA",INDEX('MASTER MENU'!$B$5:$B$504,MATCH(A23,'MASTER MENU'!$A$5:$A$504,0)))) | C23: =IF(A23="","",IF(COUNTIFS('MASTER MENU'!$A$5:$A$504,A23)=0,"BELUM ADA",INDEX('MASTER MENU'!$E$5:$E$504,MATCH(A23,'MASTER MENU'!$A$5:$A$504,0)))) | E23: =IF(D23="","",IF(COUNTIFS('MASTER BAHAN'!$A$5:$A$504,D23)=0,"BELUM ADA",INDEX('MASTER BAHAN'!$B$5:$B$504,MATCH(D23,'MASTER BAHAN'!$A$5:$A$504,0)))) | G23: =IF(D23="","",IF(COUNTIFS('MASTER BAHAN'!$A$5:$A$504,D23)=0,"BELUM ADA",INDEX('MASTER BAHAN'!$D$5:$D$504,MATCH(D23,'MASTER BAHAN'!$A$5:$A$504,0)))) | H23: =IF(D23="","",IF(COUNTIFS('MASTER BAHAN'!$A$5:$A$504,D23)=0,"BELUM ADA",INDEX('MASTER BAHAN'!$I$5:$I$504,MATCH(D23,'MASTER BAHAN'!$A$5:$A$504,0)))) | I23: =IF(A23="","",IF(OR(NOT(ISNUMBER(F23)),NOT(ISNUMBER(H23))),"BELUM LENGKAP",ROUND(F23*H23,0))) | J23: =IF(A23="","",IF(COUNTIFS($A$5:$A$504,A23,$N$5:$N$504,"BELUM LENGKAP")>0,"BELUM LENGKAP",SUMIFS($I$5:$I$504,$A$5:$A$504,A23))) | K23: =IF(A23="","",IF(COUNTIFS('MASTER MENU'!$A$5:$A$504,A23)=0,"BELUM ADA",INDEX('MASTER MENU'!$F$5:$F$504,MATCH(A23,'MASTER MENU'!$A$5:$A$504,0)))) | L23: =IF(A23="","",IF(OR(NOT(ISNUMBER(J23)),NOT(ISNUMBER(K23))),"BELUM LENGKAP",K23-J23)) | M23: =IF(A23="","",IF(OR(NOT(ISNUMBER(L23)),K23=0),"BELUM LENGKAP",L23/K23)) | N23: =IF(A23="","",IF(OR(B23="BELUM ADA",E23="BELUM ADA",NOT(ISNUMBER(F23)),F23<=0,NOT(ISNUMBER(H23)),NOT(ISNUMBER(K23))),"BELUM LENGKAP","LENGKAP"))
B24: =IF(A24="","",IF(COUNTIFS('MASTER MENU'!$A$5:$A$504,A24)=0,"BELUM ADA",INDEX('MASTER MENU'!$B$5:$B$504,MATCH(A24,'MASTER MENU'!$A$5:$A$504,0)))) | C24: =IF(A24="","",IF(COUNTIFS('MASTER MENU'!$A$5:$A$504,A24)=0,"BELUM ADA",INDEX('MASTER MENU'!$E$5:$E$504,MATCH(A24,'MASTER MENU'!$A$5:$A$504,0)))) | E24: =IF(D24="","",IF(COUNTIFS('MASTER BAHAN'!$A$5:$A$504,D24)=0,"BELUM ADA",INDEX('MASTER BAHAN'!$B$5:$B$504,MATCH(D24,'MASTER BAHAN'!$A$5:$A$504,0)))) | G24: =IF(D24="","",IF(COUNTIFS('MASTER BAHAN'!$A$5:$A$504,D24)=0,"BELUM ADA",INDEX('MASTER BAHAN'!$D$5:$D$504,MATCH(D24,'MASTER BAHAN'!$A$5:$A$504,0)))) | H24: =IF(D24="","",IF(COUNTIFS('MASTER BAHAN'!$A$5:$A$504,D24)=0,"BELUM ADA",INDEX('MASTER BAHAN'!$I$5:$I$504,MATCH(D24,'MASTER BAHAN'!$A$5:$A$504,0)))) | I24: =IF(A24="","",IF(OR(NOT(ISNUMBER(F24)),NOT(ISNUMBER(H24))),"BELUM LENGKAP",ROUND(F24*H24,0))) | J24: =IF(A24="","",IF(COUNTIFS($A$5:$A$504,A24,$N$5:$N$504,"BELUM LENGKAP")>0,"BELUM LENGKAP",SUMIFS($I$5:$I$504,$A$5:$A$504,A24))) | K24: =IF(A24="","",IF(COUNTIFS('MASTER MENU'!$A$5:$A$504,A24)=0,"BELUM ADA",INDEX('MASTER MENU'!$F$5:$F$504,MATCH(A24,'MASTER MENU'!$A$5:$A$504,0)))) | L24: =IF(A24="","",IF(OR(NOT(ISNUMBER(J24)),NOT(ISNUMBER(K24))),"BELUM LENGKAP",K24-J24)) | M24: =IF(A24="","",IF(OR(NOT(ISNUMBER(L24)),K24=0),"BELUM LENGKAP",L24/K24)) | N24: =IF(A24="","",IF(OR(B24="BELUM ADA",E24="BELUM ADA",NOT(ISNUMBER(F24)),F24<=0,NOT(ISNUMBER(H24)),NOT(ISNUMBER(K24))),"BELUM LENGKAP","LENGKAP"))
B25: =IF(A25="","",IF(COUNTIFS('MASTER MENU'!$A$5:$A$504,A25)=0,"BELUM ADA",INDEX('MASTER MENU'!$B$5:$B$504,MATCH(A25,'MASTER MENU'!$A$5:$A$504,0)))) | C25: =IF(A25="","",IF(COUNTIFS('MASTER MENU'!$A$5:$A$504,A25)=0,"BELUM ADA",INDEX('MASTER MENU'!$E$5:$E$504,MATCH(A25,'MASTER MENU'!$A$5:$A$504,0)))) | E25: =IF(D25="","",IF(COUNTIFS('MASTER BAHAN'!$A$5:$A$504,D25)=0,"BELUM ADA",INDEX('MASTER BAHAN'!$B$5:$B$504,MATCH(D25,'MASTER BAHAN'!$A$5:$A$504,0)))) | G25: =IF(D25="","",IF(COUNTIFS('MASTER BAHAN'!$A$5:$A$504,D25)=0,"BELUM ADA",INDEX('MASTER BAHAN'!$D$5:$D$504,MATCH(D25,'MASTER BAHAN'!$A$5:$A$504,0)))) | H25: =IF(D25="","",IF(COUNTIFS('MASTER BAHAN'!$A$5:$A$504,D25)=0,"BELUM ADA",INDEX('MASTER BAHAN'!$I$5:$I$504,MATCH(D25,'MASTER BAHAN'!$A$5:$A$504,0)))) | I25: =IF(A25="","",IF(OR(NOT(ISNUMBER(F25)),NOT(ISNUMBER(H25))),"BELUM LENGKAP",ROUND(F25*H25,0))) | J25: =IF(A25="","",IF(COUNTIFS($A$5:$A$504,A25,$N$5:$N$504,"BELUM LENGKAP")>0,"BELUM LENGKAP",SUMIFS($I$5:$I$504,$A$5:$A$504,A25))) | K25: =IF(A25="","",IF(COUNTIFS('MASTER MENU'!$A$5:$A$504,A25)=0,"BELUM ADA",INDEX('MASTER MENU'!$F$5:$F$504,MATCH(A25,'MASTER MENU'!$A$5:$A$504,0)))) | L25: =IF(A25="","",IF(OR(NOT(ISNUMBER(J25)),NOT(ISNUMBER(K25))),"BELUM LENGKAP",K25-J25)) | M25: =IF(A25="","",IF(OR(NOT(ISNUMBER(L25)),K25=0),"BELUM LENGKAP",L25/K25)) | N25: =IF(A25="","",IF(OR(B25="BELUM ADA",E25="BELUM ADA",NOT(ISNUMBER(F25)),F25<=0,NOT(ISNUMBER(H25)),NOT(ISNUMBER(K25))),"BELUM LENGKAP","LENGKAP"))
B26: =IF(A26="","",IF(COUNTIFS('MASTER MENU'!$A$5:$A$504,A26)=0,"BELUM ADA",INDEX('MASTER MENU'!$B$5:$B$504,MATCH(A26,'MASTER MENU'!$A$5:$A$504,0)))) | C26: =IF(A26="","",IF(COUNTIFS('MASTER MENU'!$A$5:$A$504,A26)=0,"BELUM ADA",INDEX('MASTER MENU'!$E$5:$E$504,MATCH(A26,'MASTER MENU'!$A$5:$A$504,0)))) | E26: =IF(D26="","",IF(COUNTIFS('MASTER BAHAN'!$A$5:$A$504,D26)=0,"BELUM ADA",INDEX('MASTER BAHAN'!$B$5:$B$504,MATCH(D26,'MASTER BAHAN'!$A$5:$A$504,0)))) | G26: =IF(D26="","",IF(COUNTIFS('MASTER BAHAN'!$A$5:$A$504,D26)=0,"BELUM ADA",INDEX('MASTER BAHAN'!$D$5:$D$504,MATCH(D26,'MASTER BAHAN'!$A$5:$A$504,0)))) | H26: =IF(D26="","",IF(COUNTIFS('MASTER BAHAN'!$A$5:$A$504,D26)=0,"BELUM ADA",INDEX('MASTER BAHAN'!$I$5:$I$504,MATCH(D26,'MASTER BAHAN'!$A$5:$A$504,0)))) | I26: =IF(A26="","",IF(OR(NOT(ISNUMBER(F26)),NOT(ISNUMBER(H26))),"BELUM LENGKAP",ROUND(F26*H26,0))) | J26: =IF(A26="","",IF(COUNTIFS($A$5:$A$504,A26,$N$5:$N$504,"BELUM LENGKAP")>0,"BELUM LENGKAP",SUMIFS($I$5:$I$504,$A$5:$A$504,A26))) | K26: =IF(A26="","",IF(COUNTIFS('MASTER MENU'!$A$5:$A$504,A26)=0,"BELUM ADA",INDEX('MASTER MENU'!$F$5:$F$504,MATCH(A26,'MASTER MENU'!$A$5:$A$504,0)))) | L26: =IF(A26="","",IF(OR(NOT(ISNUMBER(J26)),NOT(ISNUMBER(K26))),"BELUM LENGKAP",K26-J26)) | M26: =IF(A26="","",IF(OR(NOT(ISNUMBER(L26)),K26=0),"BELUM LENGKAP",L26/K26)) | N26: =IF(A26="","",IF(OR(B26="BELUM ADA",E26="BELUM ADA",NOT(ISNUMBER(F26)),F26<=0,NOT(ISNUMBER(H26)),NOT(ISNUMBER(K26))),"BELUM LENGKAP","LENGKAP"))
B27: =IF(A27="","",IF(COUNTIFS('MASTER MENU'!$A$5:$A$504,A27)=0,"BELUM ADA",INDEX('MASTER MENU'!$B$5:$B$504,MATCH(A27,'MASTER MENU'!$A$5:$A$504,0)))) | C27: =IF(A27="","",IF(COUNTIFS('MASTER MENU'!$A$5:$A$504,A27)=0,"BELUM ADA",INDEX('MASTER MENU'!$E$5:$E$504,MATCH(A27,'MASTER MENU'!$A$5:$A$504,0)))) | E27: =IF(D27="","",IF(COUNTIFS('MASTER BAHAN'!$A$5:$A$504,D27)=0,"BELUM ADA",INDEX('MASTER BAHAN'!$B$5:$B$504,MATCH(D27,'MASTER BAHAN'!$A$5:$A$504,0)))) | G27: =IF(D27="","",IF(COUNTIFS('MASTER BAHAN'!$A$5:$A$504,D27)=0,"BELUM ADA",INDEX('MASTER BAHAN'!$D$5:$D$504,MATCH(D27,'MASTER BAHAN'!$A$5:$A$504,0)))) | H27: =IF(D27="","",IF(COUNTIFS('MASTER BAHAN'!$A$5:$A$504,D27)=0,"BELUM ADA",INDEX('MASTER BAHAN'!$I$5:$I$504,MATCH(D27,'MASTER BAHAN'!$A$5:$A$504,0)))) | I27: =IF(A27="","",IF(OR(NOT(ISNUMBER(F27)),NOT(ISNUMBER(H27))),"BELUM LENGKAP",ROUND(F27*H27,0))) | J27: =IF(A27="","",IF(COUNTIFS($A$5:$A$504,A27,$N$5:$N$504,"BELUM LENGKAP")>0,"BELUM LENGKAP",SUMIFS($I$5:$I$504,$A$5:$A$504,A27))) | K27: =IF(A27="","",IF(COUNTIFS('MASTER MENU'!$A$5:$A$504,A27)=0,"BELUM ADA",INDEX('MASTER MENU'!$F$5:$F$504,MATCH(A27,'MASTER MENU'!$A$5:$A$504,0)))) | L27: =IF(A27="","",IF(OR(NOT(ISNUMBER(J27)),NOT(ISNUMBER(K27))),"BELUM LENGKAP",K27-J27)) | M27: =IF(A27="","",IF(OR(NOT(ISNUMBER(L27)),K27=0),"BELUM LENGKAP",L27/K27)) | N27: =IF(A27="","",IF(OR(B27="BELUM ADA",E27="BELUM ADA",NOT(ISNUMBER(F27)),F27<=0,NOT(ISNUMBER(H27)),NOT(ISNUMBER(K27))),"BELUM LENGKAP","LENGKAP"))
B28: =IF(A28="","",IF(COUNTIFS('MASTER MENU'!$A$5:$A$504,A28)=0,"BELUM ADA",INDEX('MASTER MENU'!$B$5:$B$504,MATCH(A28,'MASTER MENU'!$A$5:$A$504,0)))) | C28: =IF(A28="","",IF(COUNTIFS('MASTER MENU'!$A$5:$A$504,A28)=0,"BELUM ADA",INDEX('MASTER MENU'!$E$5:$E$504,MATCH(A28,'MASTER MENU'!$A$5:$A$504,0)))) | E28: =IF(D28="","",IF(COUNTIFS('MASTER BAHAN'!$A$5:$A$504,D28)=0,"BELUM ADA",INDEX('MASTER BAHAN'!$B$5:$B$504,MATCH(D28,'MASTER BAHAN'!$A$5:$A$504,0)))) | G28: =IF(D28="","",IF(COUNTIFS('MASTER BAHAN'!$A$5:$A$504,D28)=0,"BELUM ADA",INDEX('MASTER BAHAN'!$D$5:$D$504,MATCH(D28,'MASTER BAHAN'!$A$5:$A$504,0)))) | H28: =IF(D28="","",IF(COUNTIFS('MASTER BAHAN'!$A$5:$A$504,D28)=0,"BELUM ADA",INDEX('MASTER BAHAN'!$I$5:$I$504,MATCH(D28,'MASTER BAHAN'!$A$5:$A$504,0)))) | I28: =IF(A28="","",IF(OR(NOT(ISNUMBER(F28)),NOT(ISNUMBER(H28))),"BELUM LENGKAP",ROUND(F28*H28,0))) | J28: =IF(A28="","",IF(COUNTIFS($A$5:$A$504,A28,$N$5:$N$504,"BELUM LENGKAP")>0,"BELUM LENGKAP",SUMIFS($I$5:$I$504,$A$5:$A$504,A28))) | K28: =IF(A28="","",IF(COUNTIFS('MASTER MENU'!$A$5:$A$504,A28)=0,"BELUM ADA",INDEX('MASTER MENU'!$F$5:$F$504,MATCH(A28,'MASTER MENU'!$A$5:$A$504,0)))) | L28: =IF(A28="","",IF(OR(NOT(ISNUMBER(J28)),NOT(ISNUMBER(K28))),"BELUM LENGKAP",K28-J28)) | M28: =IF(A28="","",IF(OR(NOT(ISNUMBER(L28)),K28=0),"BELUM LENGKAP",L28/K28)) | N28: =IF(A28="","",IF(OR(B28="BELUM ADA",E28="BELUM ADA",NOT(ISNUMBER(F28)),F28<=0,NOT(ISNUMBER(H28)),NOT(ISNUMBER(K28))),"BELUM LENGKAP","LENGKAP"))
B29: =IF(A29="","",IF(COUNTIFS('MASTER MENU'!$A$5:$A$504,A29)=0,"BELUM ADA",INDEX('MASTER MENU'!$B$5:$B$504,MATCH(A29,'MASTER MENU'!$A$5:$A$504,0)))) | C29: =IF(A29="","",IF(COUNTIFS('MASTER MENU'!$A$5:$A$504,A29)=0,"BELUM ADA",INDEX('MASTER MENU'!$E$5:$E$504,MATCH(A29,'MASTER MENU'!$A$5:$A$504,0)))) | E29: =IF(D29="","",IF(COUNTIFS('MASTER BAHAN'!$A$5:$A$504,D29)=0,"BELUM ADA",INDEX('MASTER BAHAN'!$B$5:$B$504,MATCH(D29,'MASTER BAHAN'!$A$5:$A$504,0)))) | G29: =IF(D29="","",IF(COUNTIFS('MASTER BAHAN'!$A$5:$A$504,D29)=0,"BELUM ADA",INDEX('MASTER BAHAN'!$D$5:$D$504,MATCH(D29,'MASTER BAHAN'!$A$5:$A$504,0)))) | H29: =IF(D29="","",IF(COUNTIFS('MASTER BAHAN'!$A$5:$A$504,D29)=0,"BELUM ADA",INDEX('MASTER BAHAN'!$I$5:$I$504,MATCH(D29,'MASTER BAHAN'!$A$5:$A$504,0)))) | I29: =IF(A29="","",IF(OR(NOT(ISNUMBER(F29)),NOT(ISNUMBER(H29))),"BELUM LENGKAP",ROUND(F29*H29,0))) | J29: =IF(A29="","",IF(COUNTIFS($A$5:$A$504,A29,$N$5:$N$504,"BELUM LENGKAP")>0,"BELUM LENGKAP",SUMIFS($I$5:$I$504,$A$5:$A$504,A29))) | K29: =IF(A29="","",IF(COUNTIFS('MASTER MENU'!$A$5:$A$504,A29)=0,"BELUM ADA",INDEX('MASTER MENU'!$F$5:$F$504,MATCH(A29,'MASTER MENU'!$A$5:$A$504,0)))) | L29: =IF(A29="","",IF(OR(NOT(ISNUMBER(J29)),NOT(ISNUMBER(K29))),"BELUM LENGKAP",K29-J29)) | M29: =IF(A29="","",IF(OR(NOT(ISNUMBER(L29)),K29=0),"BELUM LENGKAP",L29/K29)) | N29: =IF(A29="","",IF(OR(B29="BELUM ADA",E29="BELUM ADA",NOT(ISNUMBER(F29)),F29<=0,NOT(ISNUMBER(H29)),NOT(ISNUMBER(K29))),"BELUM LENGKAP","LENGKAP"))
B30: =IF(A30="","",IF(COUNTIFS('MASTER MENU'!$A$5:$A$504,A30)=0,"BELUM ADA",INDEX('MASTER MENU'!$B$5:$B$504,MATCH(A30,'MASTER MENU'!$A$5:$A$504,0)))) | C30: =IF(A30="","",IF(COUNTIFS('MASTER MENU'!$A$5:$A$504,A30)=0,"BELUM ADA",INDEX('MASTER MENU'!$E$5:$E$504,MATCH(A30,'MASTER MENU'!$A$5:$A$504,0)))) | E30: =IF(D30="","",IF(COUNTIFS('MASTER BAHAN'!$A$5:$A$504,D30)=0,"BELUM ADA",INDEX('MASTER BAHAN'!$B$5:$B$504,MATCH(D30,'MASTER BAHAN'!$A$5:$A$504,0)))) | G30: =IF(D30="","",IF(COUNTIFS('MASTER BAHAN'!$A$5:$A$504,D30)=0,"BELUM ADA",INDEX('MASTER BAHAN'!$D$5:$D$504,MATCH(D30,'MASTER BAHAN'!$A$5:$A$504,0)))) | H30: =IF(D30="","",IF(COUNTIFS('MASTER BAHAN'!$A$5:$A$504,D30)=0,"BELUM ADA",INDEX('MASTER BAHAN'!$I$5:$I$504,MATCH(D30,'MASTER BAHAN'!$A$5:$A$504,0)))) | I30: =IF(A30="","",IF(OR(NOT(ISNUMBER(F30)),NOT(ISNUMBER(H30))),"BELUM LENGKAP",ROUND(F30*H30,0))) | J30: =IF(A30="","",IF(COUNTIFS($A$5:$A$504,A30,$N$5:$N$504,"BELUM LENGKAP")>0,"BELUM LENGKAP",SUMIFS($I$5:$I$504,$A$5:$A$504,A30))) | K30: =IF(A30="","",IF(COUNTIFS('MASTER MENU'!$A$5:$A$504,A30)=0,"BELUM ADA",INDEX('MASTER MENU'!$F$5:$F$504,MATCH(A30,'MASTER MENU'!$A$5:$A$504,0)))) | L30: =IF(A30="","",IF(OR(NOT(ISNUMBER(J30)),NOT(ISNUMBER(K30))),"BELUM LENGKAP",K30-J30)) | M30: =IF(A30="","",IF(OR(NOT(ISNUMBER(L30)),K30=0),"BELUM LENGKAP",L30/K30)) | N30: =IF(A30="","",IF(OR(B30="BELUM ADA",E30="BELUM ADA",NOT(ISNUMBER(F30)),F30<=0,NOT(ISNUMBER(H30)),NOT(ISNUMBER(K30))),"BELUM LENGKAP","LENGKAP"))
B31: =IF(A31="","",IF(COUNTIFS('MASTER MENU'!$A$5:$A$504,A31)=0,"BELUM ADA",INDEX('MASTER MENU'!$B$5:$B$504,MATCH(A31,'MASTER MENU'!$A$5:$A$504,0)))) | C31: =IF(A31="","",IF(COUNTIFS('MASTER MENU'!$A$5:$A$504,A31)=0,"BELUM ADA",INDEX('MASTER MENU'!$E$5:$E$504,MATCH(A31,'MASTER MENU'!$A$5:$A$504,0)))) | E31: =IF(D31="","",IF(COUNTIFS('MASTER BAHAN'!$A$5:$A$504,D31)=0,"BELUM ADA",INDEX('MASTER BAHAN'!$B$5:$B$504,MATCH(D31,'MASTER BAHAN'!$A$5:$A$504,0)))) | G31: =IF(D31="","",IF(COUNTIFS('MASTER BAHAN'!$A$5:$A$504,D31)=0,"BELUM ADA",INDEX('MASTER BAHAN'!$D$5:$D$504,MATCH(D31,'MASTER BAHAN'!$A$5:$A$504,0)))) | H31: =IF(D31="","",IF(COUNTIFS('MASTER BAHAN'!$A$5:$A$504,D31)=0,"BELUM ADA",INDEX('MASTER BAHAN'!$I$5:$I$504,MATCH(D31,'MASTER BAHAN'!$A$5:$A$504,0)))) | I31: =IF(A31="","",IF(OR(NOT(ISNUMBER(F31)),NOT(ISNUMBER(H31))),"BELUM LENGKAP",ROUND(F31*H31,0))) | J31: =IF(A31="","",IF(COUNTIFS($A$5:$A$504,A31,$N$5:$N$504,"BELUM LENGKAP")>0,"BELUM LENGKAP",SUMIFS($I$5:$I$504,$A$5:$A$504,A31))) | K31: =IF(A31="","",IF(COUNTIFS('MASTER MENU'!$A$5:$A$504,A31)=0,"BELUM ADA",INDEX('MASTER MENU'!$F$5:$F$504,MATCH(A31,'MASTER MENU'!$A$5:$A$504,0)))) | L31: =IF(A31="","",IF(OR(NOT(ISNUMBER(J31)),NOT(ISNUMBER(K31))),"BELUM LENGKAP",K31-J31)) | M31: =IF(A31="","",IF(OR(NOT(ISNUMBER(L31)),K31=0),"BELUM LENGKAP",L31/K31)) | N31: =IF(A31="","",IF(OR(B31="BELUM ADA",E31="BELUM ADA",NOT(ISNUMBER(F31)),F31<=0,NOT(ISNUMBER(H31)),NOT(ISNUMBER(K31))),"BELUM LENGKAP","LENGKAP"))
B32: =IF(A32="","",IF(COUNTIFS('MASTER MENU'!$A$5:$A$504,A32)=0,"BELUM ADA",INDEX('MASTER MENU'!$B$5:$B$504,MATCH(A32,'MASTER MENU'!$A$5:$A$504,0)))) | C32: =IF(A32="","",IF(COUNTIFS('MASTER MENU'!$A$5:$A$504,A32)=0,"BELUM ADA",INDEX('MASTER MENU'!$E$5:$E$504,MATCH(A32,'MASTER MENU'!$A$5:$A$504,0)))) | E32: =IF(D32="","",IF(COUNTIFS('MASTER BAHAN'!$A$5:$A$504,D32)=0,"BELUM ADA",INDEX('MASTER BAHAN'!$B$5:$B$504,MATCH(D32,'MASTER BAHAN'!$A$5:$A$504,0)))) | G32: =IF(D32="","",IF(COUNTIFS('MASTER BAHAN'!$A$5:$A$504,D32)=0,"BELUM ADA",INDEX('MASTER BAHAN'!$D$5:$D$504,MATCH(D32,'MASTER BAHAN'!$A$5:$A$504,0)))) | H32: =IF(D32="","",IF(COUNTIFS('MASTER BAHAN'!$A$5:$A$504,D32)=0,"BELUM ADA",INDEX('MASTER BAHAN'!$I$5:$I$504,MATCH(D32,'MASTER BAHAN'!$A$5:$A$504,0)))) | I32: =IF(A32="","",IF(OR(NOT(ISNUMBER(F32)),NOT(ISNUMBER(H32))),"BELUM LENGKAP",ROUND(F32*H32,0))) | J32: =IF(A32="","",IF(COUNTIFS($A$5:$A$504,A32,$N$5:$N$504,"BELUM LENGKAP")>0,"BELUM LENGKAP",SUMIFS($I$5:$I$504,$A$5:$A$504,A32))) | K32: =IF(A32="","",IF(COUNTIFS('MASTER MENU'!$A$5:$A$504,A32)=0,"BELUM ADA",INDEX('MASTER MENU'!$F$5:$F$504,MATCH(A32,'MASTER MENU'!$A$5:$A$504,0)))) | L32: =IF(A32="","",IF(OR(NOT(ISNUMBER(J32)),NOT(ISNUMBER(K32))),"BELUM LENGKAP",K32-J32)) | M32: =IF(A32="","",IF(OR(NOT(ISNUMBER(L32)),K32=0),"BELUM LENGKAP",L32/K32)) | N32: =IF(A32="","",IF(OR(B32="BELUM ADA",E32="BELUM ADA",NOT(ISNUMBER(F32)),F32<=0,NOT(ISNUMBER(H32)),NOT(ISNUMBER(K32))),"BELUM LENGKAP","LENGKAP"))
B33: =IF(A33="","",IF(COUNTIFS('MASTER MENU'!$A$5:$A$504,A33)=0,"BELUM ADA",INDEX('MASTER MENU'!$B$5:$B$504,MATCH(A33,'MASTER MENU'!$A$5:$A$504,0)))) | C33: =IF(A33="","",IF(COUNTIFS('MASTER MENU'!$A$5:$A$504,A33)=0,"BELUM ADA",INDEX('MASTER MENU'!$E$5:$E$504,MATCH(A33,'MASTER MENU'!$A$5:$A$504,0)))) | E33: =IF(D33="","",IF(COUNTIFS('MASTER BAHAN'!$A$5:$A$504,D33)=0,"BELUM ADA",INDEX('MASTER BAHAN'!$B$5:$B$504,MATCH(D33,'MASTER BAHAN'!$A$5:$A$504,0)))) | G33: =IF(D33="","",IF(COUNTIFS('MASTER BAHAN'!$A$5:$A$504,D33)=0,"BELUM ADA",INDEX('MASTER BAHAN'!$D$5:$D$504,MATCH(D33,'MASTER BAHAN'!$A$5:$A$504,0)))) | H33: =IF(D33="","",IF(COUNTIFS('MASTER BAHAN'!$A$5:$A$504,D33)=0,"BELUM ADA",INDEX('MASTER BAHAN'!$I$5:$I$504,MATCH(D33,'MASTER BAHAN'!$A$5:$A$504,0)))) | I33: =IF(A33="","",IF(OR(NOT(ISNUMBER(F33)),NOT(ISNUMBER(H33))),"BELUM LENGKAP",ROUND(F33*H33,0))) | J33: =IF(A33="","",IF(COUNTIFS($A$5:$A$504,A33,$N$5:$N$504,"BELUM LENGKAP")>0,"BELUM LENGKAP",SUMIFS($I$5:$I$504,$A$5:$A$504,A33))) | K33: =IF(A33="","",IF(COUNTIFS('MASTER MENU'!$A$5:$A$504,A33)=0,"BELUM ADA",INDEX('MASTER MENU'!$F$5:$F$504,MATCH(A33,'MASTER MENU'!$A$5:$A$504,0)))) | L33: =IF(A33="","",IF(OR(NOT(ISNUMBER(J33)),NOT(ISNUMBER(K33))),"BELUM LENGKAP",K33-J33)) | M33: =IF(A33="","",IF(OR(NOT(ISNUMBER(L33)),K33=0),"BELUM LENGKAP",L33/K33)) | N33: =IF(A33="","",IF(OR(B33="BELUM ADA",E33="BELUM ADA",NOT(ISNUMBER(F33)),F33<=0,NOT(ISNUMBER(H33)),NOT(ISNUMBER(K33))),"BELUM LENGKAP","LENGKAP"))
... B64: =IF(A64="","",IF(COUNTIFS('MASTER MENU'!$A$5:$A$504,A64)=0,"BELUM ADA",INDEX('MASTER MENU'!$B$5:$B$504,MATCH(A64,'MASTER MENU'!$A$5:$A$504,0)))) | C64: =IF(A64="","",IF(COUNTIFS('MASTER MENU'!$A$5:$A$504,A64)=0,"BELUM ADA",INDEX('MASTER MENU'!$E$5:$E$504,MATCH(A64,'MASTER MENU'!$A$5:$A$504,0)))) | E64: =IF(D64="","",IF(COUNTIFS('MASTER BAHAN'!$A$5:$A$504,D64)=0,"BELUM ADA",INDEX('MASTER BAHAN'!$B$5:$B$504,MATCH(D64,'MASTER BAHAN'!$A$5:$A$504,0)))) | G64: =IF(D64="","",IF(COUNTIFS('MASTER BAHAN'!$A$5:$A$504,D64)=0,"BELUM ADA",INDEX('MASTER BAHAN'!$D$5:$D$504,MATCH(D64,'MASTER BAHAN'!$A$5:$A$504,0)))) | H64: =IF(D64="","",IF(COUNTIFS('MASTER BAHAN'!$A$5:$A$504,D64)=0,"BELUM ADA",INDEX('MASTER BAHAN'!$I$5:$I$504,MATCH(D64,'MASTER BAHAN'!$A$5:$A$504,0)))) | I64: =IF(A64="","",IF(OR(NOT(ISNUMBER(F64)),NOT(ISNUMBER(H64))),"BELUM LENGKAP",ROUND(F64*H64,0))) | J64: =IF(A64="","",IF(COUNTIFS($A$5:$A$504,A64,$N$5:$N$504,"BELUM LENGKAP")>0,"BELUM LENGKAP",SUMIFS($I$5:$I$504,$A$5:$A$504,A64))) | K64: =IF(A64="","",IF(COUNTIFS('MASTER MENU'!$A$5:$A$504,A64)=0,"BELUM ADA",INDEX('MASTER MENU'!$F$5:$F$504,MATCH(A64,'MASTER MENU'!$A$5:$A$504,0)))) | L64: =IF(A64="","",IF(OR(NOT(ISNUMBER(J64)),NOT(ISNUMBER(K64))),"BELUM LENGKAP",K64-J64)) | M64: =IF(A64="","",IF(OR(NOT(ISNUMBER(L64)),K64=0),"BELUM LENGKAP",L64/K64)) | N64: =IF(A64="","",IF(OR(B64="BELUM ADA",E64="BELUM ADA",NOT(ISNUMBER(F64)),F64<=0,NOT(ISNUMBER(H64)),NOT(ISNUMBER(K64))),"BELUM LENGKAP","LENGKAP"))

Sheet STOK MASUK
A1: STOK MASUK
A2: Jumlah memakai satuan dasar, bukan kemasan. Catat pengeluaran pembelian bahan dengan Memengaruhi laba=Tidak.
A3: ISI MANUAL | B3: HASIL OTOMATIS | C3: ID CONTOH- = simulasi
A4: Nomor transaksi | B4: Tanggal dan waktu WIB | C4: Supplier | D4: Nomor bukti | E4: ID bahan | F4: Nama bahan | G4: Jumlah | H4: Satuan | I4: Harga beli | J4: Total | K4: Petugas | L4: Catatan | M4: Urutan item | N4: Kunci cetak
A5: CONTOH-S1 | B5: 46325.333 | C5: Supplier CONTOH | D5: BUKTI-CONTOH-1 | E5: CONTOH-B01 | F5: =IF(E5="","",IF(COUNTIFS('MASTER BAHAN'!$A$5:$A$504,E5)=0,"BELUM ADA",INDEX('MASTER BAHAN'!$B$5:$B$504,MATCH(E5,'MASTER BAHAN'!$A$5:$A$504,0)))) -> Biji kopi | G5: 100 | H5: =IF(E5="","",IF(COUNTIFS('MASTER BAHAN'!$A$5:$A$504,E5)=0,"BELUM ADA",INDEX('MASTER BAHAN'!$D$5:$D$504,MATCH(E5,'MASTER BAHAN'!$A$5:$A$504,0)))) -> gram | I5: 15000 | J5: =IF(A5="","",IF(OR(NOT(ISNUMBER(G5)),NOT(ISNUMBER(I5))),"BELUM LENGKAP",ROUND(G5*I5,0))) -> 1500000 | K5: Petugas CONTOH | L5: CONTOH - pembelian simulasi | M5: =IF(A5="","",COUNTIF($A$5:A5,A5)) -> 1 | N5: =IF(A5="","",A5&"|"&M5) -> CONTOH-S1|1
A6: CONTOH-S2 | B6: 46325.333 | C6: Supplier CONTOH | D6: BUKTI-CONTOH-2 | E6: CONTOH-B02 | F6: =IF(E6="","",IF(COUNTIFS('MASTER BAHAN'!$A$5:$A$504,E6)=0,"BELUM ADA",INDEX('MASTER BAHAN'!$B$5:$B$504,MATCH(E6,'MASTER BAHAN'!$A$5:$A$504,0)))) -> Susu UHT | G6: 100 | H6: =IF(E6="","",IF(COUNTIFS('MASTER BAHAN'!$A$5:$A$504,E6)=0,"BELUM ADA",INDEX('MASTER BAHAN'!$D$5:$D$504,MATCH(E6,'MASTER BAHAN'!$A$5:$A$504,0)))) -> ml | I6: 2400 | J6: =IF(A6="","",IF(OR(NOT(ISNUMBER(G6)),NOT(ISNUMBER(I6))),"BELUM LENGKAP",ROUND(G6*I6,0))) -> 240000 | K6: Petugas CONTOH | L6: CONTOH - pembelian simulasi | M6: =IF(A6="","",COUNTIF($A$5:A6,A6)) -> 1 | N6: =IF(A6="","",A6&"|"&M6) -> CONTOH-S2|1
A7: CONTOH-S3 | B7: 46325.333 | C7: Supplier CONTOH | D7: BUKTI-CONTOH-3 | E7: CONTOH-B03 | F7: =IF(E7="","",IF(COUNTIFS('MASTER BAHAN'!$A$5:$A$504,E7)=0,"BELUM ADA",INDEX('MASTER BAHAN'!$B$5:$B$504,MATCH(E7,'MASTER BAHAN'!$A$5:$A$504,0)))) -> Gula aren | G7: 100 | H7: =IF(E7="","",IF(COUNTIFS('MASTER BAHAN'!$A$5:$A$504,E7)=0,"BELUM ADA",INDEX('MASTER BAHAN'!$D$5:$D$504,MATCH(E7,'MASTER BAHAN'!$A$5:$A$504,0)))) -> ml | I7: 4000 | J7: =IF(A7="","",IF(OR(NOT(ISNUMBER(G7)),NOT(ISNUMBER(I7))),"BELUM LENGKAP",ROUND(G7*I7,0))) -> 400000 | K7: Petugas CONTOH | L7: CONTOH - pembelian simulasi | M7: =IF(A7="","",COUNTIF($A$5:A7,A7)) -> 1 | N7: =IF(A7="","",A7&"|"&M7) -> CONTOH-S3|1
A8: CONTOH-S4 | B8: 46325.333 | C8: Supplier CONTOH | D8: BUKTI-CONTOH-4 | E8: CONTOH-B04 | F8: =IF(E8="","",IF(COUNTIFS('MASTER BAHAN'!$A$5:$A$504,E8)=0,"BELUM ADA",INDEX('MASTER BAHAN'!$B$5:$B$504,MATCH(E8,'MASTER BAHAN'!$A$5:$A$504,0)))) -> Air mineral | G8: 100 | H8: =IF(E8="","",IF(COUNTIFS('MASTER BAHAN'!$A$5:$A$504,E8)=0,"BELUM ADA",INDEX('MASTER BAHAN'!$D$5:$D$504,MATCH(E8,'MASTER BAHAN'!$A$5:$A$504,0)))) -> ml | I8: 80 | J8: =IF(A8="","",IF(OR(NOT(ISNUMBER(G8)),NOT(ISNUMBER(I8))),"BELUM LENGKAP",ROUND(G8*I8,0))) -> 8000 | K8: Petugas CONTOH | L8: CONTOH - pembelian simulasi | M8: =IF(A8="","",COUNTIF($A$5:A8,A8)) -> 1 | N8: =IF(A8="","",A8&"|"&M8) -> CONTOH-S4|1
A9: CONTOH-S5 | B9: 46325.333 | C9: Supplier CONTOH | D9: BUKTI-CONTOH-5 | E9: CONTOH-B05 | F9: =IF(E9="","",IF(COUNTIFS('MASTER BAHAN'!$A$5:$A$504,E9)=0,"BELUM ADA",INDEX('MASTER BAHAN'!$B$5:$B$504,MATCH(E9,'MASTER BAHAN'!$A$5:$A$504,0)))) -> Bubuk matcha | G9: 100 | H9: =IF(E9="","",IF(COUNTIFS('MASTER BAHAN'!$A$5:$A$504,E9)=0,"BELUM ADA",INDEX('MASTER BAHAN'!$D$5:$D$504,MATCH(E9,'MASTER BAHAN'!$A$5:$A$504,0)))) -> gram | I9: 22000 | J9: =IF(A9="","",IF(OR(NOT(ISNUMBER(G9)),NOT(ISNUMBER(I9))),"BELUM LENGKAP",ROUND(G9*I9,0))) -> 2200000 | K9: Petugas CONTOH | L9: CONTOH - pembelian simulasi | M9: =IF(A9="","",COUNTIF($A$5:A9,A9)) -> 1 | N9: =IF(A9="","",A9&"|"&M9) -> CONTOH-S5|1
A10: CONTOH-S6 | B10: 46325.333 | C10: Supplier CONTOH | D10: BUKTI-CONTOH-6 | E10: CONTOH-B06 | F10: =IF(E10="","",IF(COUNTIFS('MASTER BAHAN'!$A$5:$A$504,E10)=0,"BELUM ADA",INDEX('MASTER BAHAN'!$B$5:$B$504,MATCH(E10,'MASTER BAHAN'!$A$5:$A$504,0)))) -> Teh celup | G10: 100 | H10: =IF(E10="","",IF(COUNTIFS('MASTER BAHAN'!$A$5:$A$504,E10)=0,"BELUM ADA",INDEX('MASTER BAHAN'!$D$5:$D$504,MATCH(E10,'MASTER BAHAN'!$A$5:$A$504,0)))) -> pcs | I10: 40000 | J10: =IF(A10="","",IF(OR(NOT(ISNUMBER(G10)),NOT(ISNUMBER(I10))),"BELUM LENGKAP",ROUND(G10*I10,0))) -> 4000000 | K10: Petugas CONTOH | L10: CONTOH - pembelian simulasi | M10: =IF(A10="","",COUNTIF($A$5:A10,A10)) -> 1 | N10: =IF(A10="","",A10&"|"&M10) -> CONTOH-S6|1
A11: CONTOH-S7 | B11: 46325.333 | C11: Supplier CONTOH | D11: BUKTI-CONTOH-7 | E11: CONTOH-B07 | F11: =IF(E11="","",IF(COUNTIFS('MASTER BAHAN'!$A$5:$A$504,E11)=0,"BELUM ADA",INDEX('MASTER BAHAN'!$B$5:$B$504,MATCH(E11,'MASTER BAHAN'!$A$5:$A$504,0)))) -> Lemon | G11: 100 | H11: =IF(E11="","",IF(COUNTIFS('MASTER BAHAN'!$A$5:$A$504,E11)=0,"BELUM ADA",INDEX('MASTER BAHAN'!$D$5:$D$504,MATCH(E11,'MASTER BAHAN'!$A$5:$A$504,0)))) -> gram | I11: 3000 | J11: =IF(A11="","",IF(OR(NOT(ISNUMBER(G11)),NOT(ISNUMBER(I11))),"BELUM LENGKAP",ROUND(G11*I11,0))) -> 300000 | K11: Petugas CONTOH | L11: CONTOH - pembelian simulasi | M11: =IF(A11="","",COUNTIF($A$5:A11,A11)) -> 1 | N11: =IF(A11="","",A11&"|"&M11) -> CONTOH-S7|1
A12: CONTOH-S8 | B12: 46325.333 | C12: Supplier CONTOH | D12: BUKTI-CONTOH-8 | E12: CONTOH-B08 | F12: =IF(E12="","",IF(COUNTIFS('MASTER BAHAN'!$A$5:$A$504,E12)=0,"BELUM ADA",INDEX('MASTER BAHAN'!$B$5:$B$504,MATCH(E12,'MASTER BAHAN'!$A$5:$A$504,0)))) -> Croissant beku | G12: 100 | H12: =IF(E12="","",IF(COUNTIFS('MASTER BAHAN'!$A$5:$A$504,E12)=0,"BELUM ADA",INDEX('MASTER BAHAN'!$D$5:$D$504,MATCH(E12,'MASTER BAHAN'!$A$5:$A$504,0)))) -> pcs | I12: 750000 | J12: =IF(A12="","",IF(OR(NOT(ISNUMBER(G12)),NOT(ISNUMBER(I12))),"BELUM LENGKAP",ROUND(G12*I12,0))) -> 75000000 | K12: Petugas CONTOH | L12: CONTOH - pembelian simulasi | M12: =IF(A12="","",COUNTIF($A$5:A12,A12)) -> 1 | N12: =IF(A12="","",A12&"|"&M12) -> CONTOH-S8|1
